Workbook
Name Slicer_Brand: #N/A
Name Slicer_Package: #N/A
Name Slicer_Product_Attributes: #N/A
Name Slicer_Size: #N/A

Sheet Source
F1: Value (in 1000 $) | I1: Volume (in 1000)
F2: 2022 | G2: 2023 | H2: YTD 24 | I2: 2022 | J2: 2023 | K2: YTD 24
A3: FreshClean | B3: BRAND | C3: PACKAGE TYPE | D3: PROTECTION / CARE | E3: PACKAGE SIZE | F3: 31416.343 | G3: 32432.398 | H3: 17382.01 | I3: 1194607.9 | J3: 1188013.2 | K3: 600950.98
A4: Nova Garbagnate | B4: MANUFACTURER | F4: 1.935 | G4: 0.624 | I4: 24.8229 | J4: 9.4086
A5: BABY 2000 (Nova Garbagnate) | B5: BRAND | F5: 1.935 | G5: 0.624 | I5: 24.8229 | J5: 9.4086
A6: BABY2000 CAMOMILLA W 20 BAG ABA SRL | B6: ITEM | C6: BAGS | D6: WITHOUT EXTRA PROTECTCARE INDICATION | E6: 20 | F6: 1.935 | G6: 0.624 | I6: 24.8229 | J6: 9.4086
A7: BeneCare | B7: MANUFACTURER | F7: 0.0109 | I7: 0.16
A8: BAMBO (BeneCare) | B8: BRAND | F8: 0.0109 | I8: 0.16
A9: BAMBO NATURE W 10 BAG | B9: ITEM | C9: BAGS | D9: WITHOUT EXTRA PROTECTCARE INDICATION | E9: 10
A10: BAMBO NATURE W 50 BAG | B10: ITEM | C10: BAGS | D10: WITHOUT EXTRA PROTECTCARE INDICATION | E10: 50
A11: BAMBO NATURE 0%PERFUME W 80 BAG | B11: ITEM | C11: BAGS | D11: WITHOUT EXTRA PROTECTCARE INDICATION | E11: 80
A12: BAMBO NATURE W 80 BAG KAPAK | B12: ITEM | C12: BAGS | D12: WITHOUT EXTRA PROTECTCARE INDICATION | E12: 80 | F12: 0.0109 | I12: 0.16
A13: VigaLife | B13: MANUFACTURER | F13: 3341.5013 | G13: 3428.0437 | H13: 1852.1969 | I13: 125970.25 | J13: 127615.61 | K13: 64977.618
A14: BABY CREMA (VigaLife) | B14: BRAND | F14: 3341.5013 | G14: 3428.0437 | H14: 1852.1969 | I14: 125970.25 | J14: 127615.61 | K14: 64977.618
A15: BABY CREMA PLAY TIME CAMOMILE W 100 PINK | B15: ITEM | C15: BAGS | D15: PH BALANCED | E15: 100 | F15: 81.4674 | G15: 92.903 | H15: 52.5119 | I15: 2980.7043 | J15: 3415.3554 | K15: 1823.0734
A16: BABYCREMA PLAYTIME CAMOMILE W 100 ORANGE | B16: ITEM | C16: BAGS | D16: PH BALANCED | E16: 100 | F16: 165.228 | G16: 172.6843 | H16: 91.1357 | I16: 5930.9056 | J16: 6183.6273 | K16: 3125.7987
A17: BABY CREMA CAMOMIL W 120 BAG KAPAK | B17: ITEM | C17: BAGS | D17: PH BALANCED | E17: 120 | F17: 842.8724 | G17: 745.3358 | H17: 366.9589 | I17: 38888.54 | J17: 31985 | K17: 14135.173
A18: BABY CREMA ALOE 15 BAG | B18: ITEM | C18: BAGS | D18: WITHOUT EXTRA PROTECTCARE INDICATION | E18: 15 | F18: 12.7748 | G18: 10.866 | H18: 6.7743 | I18: 151.2668 | J18: 127.1868 | K18: 77.4594
A19: BABY CREMA CAMOMIL W 15 BAG | B19: ITEM | C19: BAGS | D19: WITHOUT EXTRA PROTECTCARE INDICATION | E19: 15 | F19: 20.0553 | G19: 17.8361 | H19: 11.1871 | I19: 231.0878 | J19: 217.7118 | K19: 141.008
A20: BABY CREMA PH5.5 W 3X15/1FR BAG &&& | B20: ITEM | C20: BAGS | D20: PH BALANCED | E20: 15 | F20: 1.2461 | G20: 7.7651 | H20: 2.2378 | I20: 20.9609 | J20: 127.6666 | K20: 33.571
A21: BABY CREMA WATER 99% W 15 BAG | B21: ITEM | C21: BAGS | D21: ALCOHOL FREE | E21: 15 | F21: 9.6472 | G21: 10.7577 | H21: 7.0723 | I21: 112.2061 | J21: 131.0528 | K21: 85.7198
A22: BABY CREMA CAMOMIL W 40 BAG | B22: ITEM | C22: BAGS | D22: WITHOUT EXTRA PROTECTCARE INDICATION | E22: 40 | F22: 0.1235 | I22: 2.28
A23: BABY CREMA COTTON&PANTENOL W 4X56 BAG | B23: ITEM | C23: BAGS | D23: PH BALANCED | E23: 56 | H23: 7.1128 | K23: 247.099
A24: BABY CREMA COTTON&PANTENOL W 56 BAG | B24: ITEM | C24: BAGS | D24: PH BALANCED | E24: 56 | F24: 0.1831 | G24: 0.1116 | H24: 0.387 | I24: 5.8885 | J24: 3.791 | K24: 14.3827
A25: BABY CREMA ALOE 64 BAG | B25: ITEM | C25: BAGS | D25: WITHOUT EXTRA PROTECTCARE INDICATION | E25: 64 | F25: 1.8939 | H25: 0.2252 | I25: 49.9726 | K25: 6.9501
A26: BABY CREMA CAMOMIL W 64 BAG | B26: ITEM | C26: BAGS | D26: WITHOUT EXTRA PROTECTCARE INDICATION | E26: 64 | F26: 1.3515 | G26: 0.0017 | I26: 37.3226 | J26: 0.064
A27: BABY CREMA PLAY TIME CAMOMIL W 64 BAG | B27: ITEM | C27: BAGS | D27: PH BALANCED | E27: 64 | F27: 5.8978 | G27: 0.1087 | I27: 169.5808 | J27: 3.3823
A28: BABYCREMA CAMOMIL W 4X64 BAG SUPERTSENA | B28: ITEM | C28: BAGS | D28: ALCOHOL FREE | E28: 64 | F28: 0.6967 | G28: 28.3929 | H28: 2.1978 | I28: 25.6063 | J28: 1226.3662 | K28: 96.4388
A29: BABY CREMA ALOE&ALMOND OIL W 72 BAG | B29: ITEM | C29: BAGS | D29: WITHOUT EXTRA PROTECTCARE INDICATION | E29: 72 | F29: 117.6534 | G29: 68.1177 | H29: 28.3499 | I29: 3055.9406 | J29: 1781.8513 | K29: 711.0772
A30: BABY CREMA CAMOMIL&ALMOND W 72 BAG | B30: ITEM | C30: BAGS | D30: WITHOUT EXTRA PROTECTCARE INDICATION | E30: 72 | F30: 38.6778 | G30: 31.4983 | H30: 9.7551 | I30: 954.1122 | J30: 803.2852 | K30: 236.1983
A31: BABY CREMA COTTON W 2X72BAG50%OT TS.VTOR | B31: ITEM | C31: BAGS | D31: PH BALANCED | E31: 72 | F31: 0.0612 | I31: 1.6046
A32: BABY CREMA COTTON&PANTENOL W 72 BAG | B32: ITEM | C32: BAGS | D32: PH BALANCED | E32: 72 | F32: 36.5218 | G32: 5.1192 | H32: 1.1213 | I32: 1199.5277 | J32: 135.3687 | K32: 30.5544
A33: BABY CREMA NEVEN PH5.5 W 72 BAG | B33: ITEM | C33: BAGS | D33: PH BALANCED | E33: 72 | F33: 21.9583 | G33: 39.4671 | H33: 10.7844 | I33: 726.314 | J33: 1508.4714 | K33: 314.5264
A34: BABY CREMA SMRADLIKA PH5.5 W 72 BAG | B34: ITEM | C34: BAGS | D34: PH BALANCED | E34: 72 | F34: 27.9836 | G34: 162.4105 | H34: 103.168 | I34: 928.8153 | J34: 5484.9445 | K34: 3446.0195
A35: BABY CREMA WATER 99% W 72 BAG | B35: ITEM | C35: BAGS | D35: WITHOUT EXTRA PROTECTCARE INDICATION | E35: 72 | F35: 221.1702 | G35: 159.9896 | H35: 77.8656 | I35: 6715.8593 | J35: 4333.2688 | K35: 2035.5381
A36: BABYCREMA CAMOMILE W 2X72BAG50%OTTS.VTOR | B36: ITEM | C36: BAGS | D36: PH BALANCED | E36: 72 | F36: 6.4487 | G36: 1.6864 | I36: 194.6519 | J36: 50.7003
A37: BABYCREMA COTTON&PANTENOL W 3X72/1FR BAG | B37: ITEM | C37: BAGS | D37: PH BALANCED | E37: 72
A38: BABYCREMA PLAYTIME CAMOMIL W 72 BAG KAPA | B38: ITEM | C38: BAGS | D38: PH BALANCED | E38: 72 | F38: 1663.8369 | G38: 1815.6597 | H38: 1049.2486 | I38: 62012.673 | J38: 68679.966 | K38: 37856.882
A39: BABY CREMA ALOE W 80 BAG | B39: ITEM | C39: BAGS | D39: WITHOUT EXTRA PROTECTCARE INDICATION | E39: 80 | F39: 1.7698 | G39: 0.3617 | H39: 0.2081 | I39: 50.2205 | J39: 12.0681 | K39: 5.4643
A40: BABY CREMA CAMOMIL W 80 BAG | B40: ITEM | C40: BAGS | D40: WITHOUT EXTRA PROTECTCARE INDICATION | E40: 80 | F40: 61.9819 | G40: 56.9702 | H40: 23.8948 | I40: 1524.2099 | J40: 1404.4859 | K40: 554.6842
...

Sheet Structured Source
B1: Product Description | C1: Manufacturer | D1: Brand | E1: Package | F1: Product Attributes | G1: Size | H1: 2022 Value | I1: 2023 Value | J1: YTD 24 Value | K1: 2022 Volume | L1: 2023 Volume | M1: YTD 24 Volume
B2: BABY2000 CAMOMILLA W 20 BAG ABA SRL | C2: Nova Garbagnate | D2: BABY2000 | E2: BAGS | F2: WITHOUT EXTRA PROTECTCARE INDICATION | G2: 20 | H2: 1.935 | I2: 0.624 | K2: 24.8229 | L2: 9.4086
B3: BAMBO NATURE W 80 BAG KAPAK | C3: BeneCare | D3: BAMBO NATURE | E3: BAGS | F3: WITHOUT EXTRA PROTECTCARE INDICATION | G3: 80 | H3: 0.0109 | K3: 0.16
B4: BABY CREMA PLAY TIME CAMOMILE W 100 PINK | C4: VigaLife | D4: BABY CREMA | E4: BAGS | F4: PH BALANCED | G4: 100 | H4: 81.4674 | I4: 92.903 | J4: 52.5119 | K4: 2980.7043 | L4: 3415.3554 | M4: 1823.0734
B5: BABYCREMA PLAYTIME CAMOMILE W 100 ORANGE | C5: VigaLife | D5: BABY CREMA | E5: BAGS | F5: PH BALANCED | G5: 100 | H5: 165.228 | I5: 172.6843 | J5: 91.1357 | K5: 5930.9056 | L5: 6183.6273 | M5: 3125.7987
B6: BABY CREMA CAMOMIL W 120 BAG KAPAK | C6: VigaLife | D6: BABY CREMA | E6: BAGS | F6: PH BALANCED | G6: 120 | H6: 842.8724 | I6: 745.3358 | J6: 366.9589 | K6: 38888.54 | L6: 31985 | M6: 14135.173
B7: BABY CREMA ALOE 15 BAG | C7: VigaLife | D7: BABY CREMA | E7: BAGS | F7: WITHOUT EXTRA PROTECTCARE INDICATION | G7: 15 | H7: 12.7748 | I7: 10.866 | J7: 6.7743 | K7: 151.2668 | L7: 127.1868 | M7: 77.4594
B8: BABY CREMA CAMOMIL W 15 BAG | C8: VigaLife | D8: BABY CREMA | E8: BAGS | F8: WITHOUT EXTRA PROTECTCARE INDICATION | G8: 15 | H8: 20.0553 | I8: 17.8361 | J8: 11.1871 | K8: 231.0878 | L8: 217.7118 | M8: 141.008
B9: BABY CREMA PH5.5 W 3X15/1FR BAG &&& | C9: VigaLife | D9: BABY CREMA | E9: BAGS | F9: PH BALANCED | G9: 15 | H9: 1.2461 | I9: 7.7651 | J9: 2.2378 | K9: 20.9609 | L9: 127.6666 | M9: 33.571
B10: BABY CREMA WATER 99% W 15 BAG | C10: VigaLife | D10: BABY CREMA | E10: BAGS | F10: ALCOHOL FREE | G10: 15 | H10: 9.6472 | I10: 10.7577 | J10: 7.0723 | K10: 112.2061 | L10: 131.0528 | M10: 85.7198
B11: BABY CREMA CAMOMIL W 40 BAG | C11: VigaLife | D11: BABY CREMA | E11: BAGS | F11: WITHOUT EXTRA PROTECTCARE INDICATION | G11: 40 | H11: 0.1235 | K11: 2.28
B12: BABY CREMA COTTON&PANTENOL W 4X56 BAG | C12: VigaLife | D12: BABY CREMA | E12: BAGS | F12: PH BALANCED | G12: 56 | J12: 7.1128 | M12: 247.099
B13: BABY CREMA COTTON&PANTENOL W 56 BAG | C13: VigaLife | D13: BABY CREMA | E13: BAGS | F13: PH BALANCED | G13: 56 | H13: 0.1831 | I13: 0.1116 | J13: 0.387 | K13: 5.8885 | L13: 3.791 | M13: 14.3827
B14: BABY CREMA ALOE 64 BAG | C14: VigaLife | D14: BABY CREMA | E14: BAGS | F14: WITHOUT EXTRA PROTECTCARE INDICATION | G14: 64 | H14: 1.8939 | J14: 0.2252 | K14: 49.9726 | M14: 6.9501
B15: BABY CREMA CAMOMIL W 64 BAG | C15: VigaLife | D15: BABY CREMA | E15: BAGS | F15: WITHOUT EXTRA PROTECTCARE INDICATION | G15: 64 | H15: 1.3515 | I15: 0.0017 | K15: 37.3226 | L15: 0.064
B16: BABY CREMA PLAY TIME CAMOMIL W 64 BAG | C16: VigaLife | D16: BABY CREMA | E16: BAGS | F16: PH BALANCED | G16: 64 | H16: 5.8978 | I16: 0.1087 | K16: 169.5808 | L16: 3.3823
B17: BABYCREMA CAMOMIL W 4X64 BAG SUPERTSENA | C17: VigaLife | D17: BABY CREMA | E17: BAGS | F17: ALCOHOL FREE | G17: 64 | H17: 0.6967 | I17: 28.3929 | J17: 2.1978 | K17: 25.6063 | L17: 1226.3662 | M17: 96.4388
B18: BABY CREMA ALOE&ALMOND OIL W 72 BAG | C18: VigaLife | D18: BABY CREMA | E18: BAGS | F18: WITHOUT EXTRA PROTECTCARE INDICATION | G18: 72 | H18: 117.6534 | I18: 68.1177 | J18: 28.3499 | K18: 3055.9406 | L18: 1781.8513 | M18: 711.0772
B19: BABY CREMA CAMOMIL&ALMOND W 72 BAG | C19: VigaLife | D19: BABY CREMA | E19: BAGS | F19: WITHOUT EXTRA PROTECTCARE INDICATION | G19: 72 | H19: 38.6778 | I19: 31.4983 | J19: 9.7551 | K19: 954.1122 | L19: 803.2852 | M19: 236.1983
B20: BABY CREMA COTTON W 2X72BAG50%OT TS.VTOR | C20: VigaLife | D20: BABY CREMA | E20: BAGS | F20: PH BALANCED | G20: 72 | H20: 0.0612 | K20: 1.6046
B21: BABY CREMA COTTON&PANTENOL W 72 BAG | C21: VigaLife | D21: BABY CREMA | E21: BAGS | F21: PH BALANCED | G21: 72 | H21: 36.5218 | I21: 5.1192 | J21: 1.1213 | K21: 1199.5277 | L21: 135.3687 | M21: 30.5544
B22: BABY CREMA NEVEN PH5.5 W 72 BAG | C22: VigaLife | D22: BABY CREMA | E22: BAGS | F22: PH BALANCED | G22: 72 | H22: 21.9583 | I22: 39.4671 | J22: 10.7844 | K22: 726.314 | L22: 1508.4714 | M22: 314.5264
B23: BABY CREMA SMRADLIKA PH5.5 W 72 BAG | C23: VigaLife | D23: BABY CREMA | E23: BAGS | F23: PH BALANCED | G23: 72 | H23: 27.9836 | I23: 162.4105 | J23: 103.168 | K23: 928.8153 | L23: 5484.9445 | M23: 3446.0195
B24: BABY CREMA WATER 99% W 72 BAG | C24: VigaLife | D24: BABY CREMA | E24: BAGS | F24: WITHOUT EXTRA PROTECTCARE INDICATION | G24: 72 | H24: 221.1702 | I24: 159.9896 | J24: 77.8656 | K24: 6715.8593 | L24: 4333.2688 | M24: 2035.5381
B25: BABYCREMA CAMOMILE W 2X72BAG50%OTTS.VTOR | C25: VigaLife | D25: BABY CREMA | E25: BAGS | F25: PH BALANCED | G25: 72 | H25: 6.4487 | I25: 1.6864 | K25: 194.6519 | L25: 50.7003
B26: BABYCREMA PLAYTIME CAMOMIL W 72 BAG KAPA | C26: VigaLife | D26: BABY CREMA | E26: BAGS | F26: PH BALANCED | G26: 72 | H26: 1663.8369 | I26: 1815.6597 | J26: 1049.2486 | K26: 62012.673 | L26: 68679.966 | M26: 37856.882
B27: BABY CREMA ALOE W 80 BAG | C27: VigaLife | D27: BABY CREMA | E27: BAGS | F27: WITHOUT EXTRA PROTECTCARE INDICATION | G27: 80 | H27: 1.7698 | I27: 0.3617 | J27: 0.2081 | K27: 50.2205 | L27: 12.0681 | M27: 5.4643
B28: BABY CREMA CAMOMIL W 80 BAG | C28: VigaLife | D28: BABY CREMA | E28: BAGS | F28: WITHOUT EXTRA PROTECTCARE INDICATION | G28: 80 | H28: 61.9819 | I28: 56.9702 | J28: 23.8948 | K28: 1524.2099 | L28: 1404.4859 | M28: 554.6842
B29: LINDY VITAMIN E PH5.5 W 120 BAG | C29: Intelligent Initiative | D29: LINDY | E29: BAGS | F29: PH BALANCED | G29: 120 | H29: 78.228 | I29: 99.0305 | J29: 56.6741 | K29: 4816.5708 | L29: 5822.6244 | M29: 2923.4183
B30: LINDY ALOE VERA&VIT E W 64 BAG | C30: Intelligent Initiative | D30: LINDY | E30: BAGS | F30: WITHOUT EXTRA PROTECTCARE INDICATION | G30: 64 | H30: 11.11 | I30: 8.9544 | J30: 2.2329 | K30: 523.1682 | L30: 387.3223 | M30: 84.4284
B31: LINDY ALOE VERA&VIT E W 64 BAG KAPAK | C31: Intelligent Initiative | D31: LINDY | E31: BAGS | F31: WITHOUT EXTRA PROTECTCARE INDICATION | G31: 64 | H31: 79.953 | I31: 73.7571 | J31: 40.3623 | K31: 3388.3482 | L31: 2840.8843 | M31: 1387.0689
B32: LINDY CAMOMILE W 64 BAG | C32: Intelligent Initiative | D32: LINDY | E32: BAGS | F32: WITHOUT EXTRA PROTECTCARE INDICATION | G32: 64 | H32: 12.195 | I32: 8.5598 | J32: 1.6517 | K32: 553.0388 | L32: 369.8305 | M32: 64.1001
B33: LINDY CAMOMILE W 64 BAG KAPAK | C33: Intelligent Initiative | D33: LINDY | E33: BAGS | F33: WITHOUT EXTRA PROTECTCARE INDICATION | G33: 64 | H33: 60.5108 | I33: 52.406 | J33: 30.1228 | K33: 2540.1292 | L33: 2011.4869 | M33: 1066.0352
B34: LINDY CREAM W 64 BAG KAPAK | C34: Intelligent Initiative | D34: LINDY | E34: BAGS | F34: WITHOUT EXTRA PROTECTCARE INDICATION | G34: 64 | H34: 47.8005 | I34: 51.1991 | J34: 29.6906 | K34: 1970.2178 | L34: 1924.2328 | M34: 1027.8572
B35: LINDY CREAM&VIT.E PH5.5 W 64 BAG | C35: Intelligent Initiative | D35: LINDY | E35: BAGS | F35: PH BALANCED | G35: 64 | I35: 3.2536 | J35: 4.3144 | L35: 139.3498 | M35: 169.8469
B36: LINDY OLIVE OIL EXTR. PH5.5 W 64 BAG | C36: Intelligent Initiative | D36: LINDY | E36: BAGS | F36: PH BALANCED | G36: 64 | H36: 5.5922 | I36: 5.3672 | J36: 2.5727 | K36: 261.0479 | L36: 232.436 | M36: 93.9955
B37: LINDY OLIVE OIL EXTR. W 64 BAG KAPAK | C37: Intelligent Initiative | D37: LINDY | E37: BAGS | F37: PH BALANCED | G37: 64 | H37: 53.4907 | I37: 44.7837 | J37: 26.4409 | K37: 2262.5698 | L37: 1667.4681 | M37: 920.8814
B38: LINDY SENSITIVE COTTON PH5.5 W 64 BAG | C38: Intelligent Initiative | D38: LINDY | E38: BAGS | F38: SENSITIVE | G38: 64 | H38: 8.271 | I38: 9.931 | J38: 1.1805 | K38: 392.0086 | L38: 426.1969 | M38: 46.2808
B39: LINDY SENSITIVE W 64 BAG KAPAK | C39: Intelligent Initiative | D39: LINDY | E39: BAGS | F39: SENSITIVE | G39: 64 | H39: 70.5623 | I39: 56.7856 | J39: 30.7966 | K39: 2842.322 | L39: 2121.0371 | M39: 1067.8224
B40: LINDY WHITE TEA&VIT E W 64 BAG | C40: Intelligent Initiative | D40: LINDY | E40: BAGS | F40: PH BALANCED | G40: 64 | H40: 34.4959 | I40: 35.3334 | J40: 28.0782 | K40: 1446.3839 | L40: 1359.9783 | M40: 967.9162
...

Sheet Pivot
A3: Row Labels | B3: Sum of 2022 Value | C3: Sum of 2023 Value | D3: Sum of YTD 24 Value | E3: Sum of 2022 Volume | F3: Sum of 2023 Volume | G3: Sum of YTD 24 Volume
A4: AlpineMeadow | B4: 113.3091 | C4: 81.3138 | D4: 48.2973 | E4: 1483.433 | F4: 1045.7731 | G4: 598.3963
A5: ArborChemistry | B5: 0.7052 | E5: 47.3253
A6: Arkana PaperCraft | B6: 1.5393 | C6: 2.0579 | D6: 0.6821 | E6: 71.3574 | F6: 96.8431 | G6: 27.711
A7: ArkPapers | B7: 104.6661 | C7: 94.425 | D7: 45.9484 | E7: 5728.6424 | F7: 5002.3732 | G7: 2228.9191
A8: ArsenicChem | B8: 11.9632 | C8: 18.1364 | D8: 9.0269 | E8: 603.2765 | F8: 937.4516 | G8: 454.7745
A9: Ataman Industries | D9: 0.0557 | G9: 1.7426
A10: AvellinoGroup SRL | B10: 9.1873 | E10: 430.1689
A11: AxisOn Group | B11: 471.6444 | C11: 448.0014 | D11: 276.1402 | E11: 13724.156 | F11: 13181.351 | G11: 8823.524
A12: BeneCare | B12: 0.0109 | E12: 0.16
A13: BioRealm Corp | B13: 0.5204 | C13: 1.6072 | D13: 0.1642 | E13: 10.5198 | F13: 34.4998 | G13: 3.1461
A14: BladeSon LTD | B14: 55.0964 | C14: 43.3482 | D14: 24.5302 | E14: 2000.4356 | F14: 1647.0114 | G14: 929.3516
A15: BroadLeaf Group | C15: 4.4635 | D15: 5.901 | F15: 231.3342 | G15: 348.1982
A16: BrothersFlyProducts SAN A.S. | B16: 0.3329 | C16: 0.0272 | D16: 1.4402 | E16: 16.5857 | F16: 2.2243 | G16: 35.5606
A17: CapPlus | B17: 0.0119 | E17: 0.14
A18: CelticWind Ltd | B18: 220.2778 | C18: 271.9984 | D18: 141.2388 | E18: 1748.9224 | F18: 2358.5312 | G18: 1240.7413
A19: ChillClean | C19: 1.8077 | D19: 54.2507 | F19: 127.6024 | G19: 2956.24
A20: CleanHarper | B20: 230.7483 | C20: 302.0658 | D20: 144.0024 | E20: 11792.665 | F20: 15544.818 | G20: 7126.6585
A21: ClearSight | B21: 36.026 | C21: 55.2297 | D21: 85.1395 | E21: 1024.5518 | F21: 1623.7087 | G21: 2439.0853
A22: CodeInt B.V. | B22: 0.0103 | E22: 0.3876
A23: ColorSan | B23: 65.8638 | C23: 45.3404 | D23: 13.16 | E23: 4126.7389 | F23: 2357.3103 | G23: 741.5008
A24: CosmicChem | B24: 11.1817 | C24: 15.1816 | D24: 9.6165 | E24: 586.3808 | F24: 752.9448 | G24: 438.7639
A25: Cosmopolitan Italy | C25: 0.1202 | F25: 2.4086
A26: CottonUnion | B26: 212.4264 | C26: 118.9335 | D26: 32.277 | E26: 11963.104 | F26: 6284.8912 | G26: 1340.7377
A27: Creativa Worldwide | C27: 13.192 | D27: 52.8111 | F27: 565.5391 | G27: 2091.2261
A28: CrescentTextile SAN | D28: 0.098 | G28: 3.3592
A29: CultureSana | B29: 3.1665 | C29: 2.1887 | D29: 0.463 | E29: 65.2032 | F29: 50.3704 | G29: 10.1665
A30: Daisy Cotton Cosmetics | B30: 0.3602 | C30: 0.0521 | D30: 0.0094 | E30: 19.0651 | F30: 2.6206 | G30: 0.48
A31: EnkaHygiene | B31: 8.9794 | E31: 618.4688
A32: ErusHealth Products | B32: 28.1013 | C32: 242.1946 | D32: 67.6063 | E32: 1283.3092 | F32: 13602.249 | G32: 3938.0098
A33: Esburg Health | C33: 170.665 | D33: 101.533 | F33: 10947.356 | G33: 5713.8588
A34: EssentialsCo | B34: 8.6899 | C34: 1.198 | D34: 0.1404 | E34: 161.0712 | F34: 29.0835 | G34: 1.4402
A35: EuroPack Communications SRL | B35: 60.8991 | C35: 35.9796 | D35: 13.2828 | E35: 1646.9927 | F35: 1006.4904 | G35: 408.4543
A36: EveCraft | B36: 15.6526 | C36: 38.2643 | D36: 12.5625 | E36: 709.8645 | F36: 1422.4409 | G36: 440.1789
A37: FabreStone | B37: 1.4567 | C37: 0.9711 | D37: 0.4412 | E37: 8.1129 | F37: 4.8049 | G37: 2.4375
A38: FemmeBeauty | B38: 9.2643 | C38: 0.1729 | D38: 0.003 | E38: 358.9599 | F38: 4.9572 | G38: 0.072
A39: FoodTNCR | B39: 2.0786 | C39: 0.0712 | E39: 104.0465 | F39: 3.8216
A40: Fragrantium S.A. | B40: 0.0445 | C40: 0.062 | E40: 0.3676 | F40: 0.4838
A41: Fulya Beauty | B41: 1012.923 | C41: 822.9812 | D41: 367.9878 | E41: 57405.587 | F41: 44546.772 | G41: 18766.233
A42: Giga S.A. | B42: 336.5157 | C42: 318.6227 | D42: 125.7655 | E42: 10226.771 | F42: 9928.9133 | G42: 3640.5187
...

Sheet Report
B1: Report
M3: YOY Growth 2022-2023%
B4: in 000s | C4: 2022 Value | D4: 2022 Volume | E4: Average price | F4: 2023 Value | G4: 2023 Volume | H4: Average price | I4: YTD 24 Value | J4: YTD 24 Volume | K4: Average price | M4: Value | N4: Volume | O4: Average price
B5: Nova Garbagnate | C5: =IFERROR(GETPIVOTDATA("Sum of "&C$4,Pivot!$A$3,"Manufacturer",$B5),0) -> 1.935 | D5: =IFERROR(GETPIVOTDATA("Sum of "&D$4,Pivot!$A$3,"Manufacturer",$B5),0) -> 24.8229 | E5: =IFERROR(C5/D5*1000,"n.a.") -> 77.952213 | F5: =IFERROR(GETPIVOTDATA("Sum of "&F$4,Pivot!$A$3,"Manufacturer",$B5),0) -> 0.624 | G5: =IFERROR(GETPIVOTDATA("Sum of "&G$4,Pivot!$A$3,"Manufacturer",$B5),0) -> 9.4086 | H5: =IFERROR(F5/G5*1000,"n.a.") -> 66.322301 | I5: =IFERROR(GETPIVOTDATA("Sum of "&I$4,Pivot!$A$3,"Manufacturer",$B5),0) -> 0 | J5: =IFERROR(GETPIVOTDATA("Sum of "&J$4,Pivot!$A$3,"Manufacturer",$B5),0) -> 0 | K5: =IFERROR(I5/J5*1000,"n.a.") -> n.a. | M5: =IFERROR(F5/C5-1,"n.a.") -> -0.67751938 | N5: =IFERROR(G5/D5-1,"n.a.") -> -0.62097096 | O5: =IFERROR(H5/E5-1,"n.a.") -> -0.14919285
B6: BeneCare | C6: =IFERROR(GETPIVOTDATA("Sum of "&C$4,Pivot!$A$3,"Manufacturer",$B6),0) -> 0.0109 | D6: =IFERROR(GETPIVOTDATA("Sum of "&D$4,Pivot!$A$3,"Manufacturer",$B6),0) -> 0.16 | E6: =IFERROR(C6/D6*1000,"n.a.") -> 68.125 | F6: =IFERROR(GETPIVOTDATA("Sum of "&F$4,Pivot!$A$3,"Manufacturer",$B6),0) -> 0 | G6: =IFERROR(GETPIVOTDATA("Sum of "&G$4,Pivot!$A$3,"Manufacturer",$B6),0) -> 0 | H6: =IFERROR(F6/G6*1000,"n.a.") -> n.a. | I6: =IFERROR(GETPIVOTDATA("Sum of "&I$4,Pivot!$A$3,"Manufacturer",$B6),0) -> 0 | J6: =IFERROR(GETPIVOTDATA("Sum of "&J$4,Pivot!$A$3,"Manufacturer",$B6),0) -> 0 | K6: =IFERROR(I6/J6*1000,"n.a.") -> n.a. | M6: =IFERROR(F6/C6-1,"n.a.") -> -1 | N6: =IFERROR(G6/D6-1,"n.a.") -> -1 | O6: =IFERROR(H6/E6-1,"n.a.") -> n.a.
B7: VigaLife | C7: =IFERROR(GETPIVOTDATA("Sum of "&C$4,Pivot!$A$3,"Manufacturer",$B7),0) -> 3341.5013 | D7: =IFERROR(GETPIVOTDATA("Sum of "&D$4,Pivot!$A$3,"Manufacturer",$B7),0) -> 125970.25 | E7: =IFERROR(C7/D7*1000,"n.a.") -> 26.526115 | F7: =IFERROR(GETPIVOTDATA("Sum of "&F$4,Pivot!$A$3,"Manufacturer",$B7),0) -> 3428.0433 | G7: =IFERROR(GETPIVOTDATA("Sum of "&G$4,Pivot!$A$3,"Manufacturer",$B7),0) -> 127615.61 | H7: =IFERROR(F7/G7*1000,"n.a.") -> 26.862256 | I7: =IFERROR(GETPIVOTDATA("Sum of "&I$4,Pivot!$A$3,"Manufacturer",$B7),0) -> 1852.1966 | J7: =IFERROR(GETPIVOTDATA("Sum of "&J$4,Pivot!$A$3,"Manufacturer",$B7),0) -> 64977.618 | K7: =IFERROR(I7/J7*1000,"n.a.") -> 28.505148 | M7: =IFERROR(F7/C7-1,"n.a.") -> 0.025899137 | N7: =IFERROR(G7/D7-1,"n.a.") -> 0.013061531 | O7: =IFERROR(H7/E7-1,"n.a.") -> 0.012672089
B8: Intelligent Initiative | C8: =IFERROR(GETPIVOTDATA("Sum of "&C$4,Pivot!$A$3,"Manufacturer",$B8),0) -> 511.7809 | D8: =IFERROR(GETPIVOTDATA("Sum of "&D$4,Pivot!$A$3,"Manufacturer",$B8),0) -> 23199.702 | E8: =IFERROR(C8/D8*1000,"n.a.") -> 22.059805 | F8: =IFERROR(GETPIVOTDATA("Sum of "&F$4,Pivot!$A$3,"Manufacturer",$B8),0) -> 507.3046 | G8: =IFERROR(GETPIVOTDATA("Sum of "&G$4,Pivot!$A$3,"Manufacturer",$B8),0) -> 21680.539 | H8: =IFERROR(F8/G8*1000,"n.a.") -> 23.399077 | I8: =IFERROR(GETPIVOTDATA("Sum of "&I$4,Pivot!$A$3,"Manufacturer",$B8),0) -> 295.7135 | J8: =IFERROR(GETPIVOTDATA("Sum of "&J$4,Pivot!$A$3,"Manufacturer",$B8),0) -> 11434.484 | K8: =IFERROR(I8/J8*1000,"n.a.") -> 25.861552 | M8: =IFERROR(F8/C8-1,"n.a.") -> -0.0087465163 | N8: =IFERROR(G8/D8-1,"n.a.") -> -0.065482017 | O8: =IFERROR(H8/E8-1,"n.a.") -> 0.060710978
B9: BroadLeaf Group | C9: =IFERROR(GETPIVOTDATA("Sum of "&C$4,Pivot!$A$3,"Manufacturer",$B9),0) -> 0 | D9: =IFERROR(GETPIVOTDATA("Sum of "&D$4,Pivot!$A$3,"Manufacturer",$B9),0) -> 0 | E9: =IFERROR(C9/D9*1000,"n.a.") -> n.a. | F9: =IFERROR(GETPIVOTDATA("Sum of "&F$4,Pivot!$A$3,"Manufacturer",$B9),0) -> 4.4635 | G9: =IFERROR(GETPIVOTDATA("Sum of "&G$4,Pivot!$A$3,"Manufacturer",$B9),0) -> 231.3342 | H9: =IFERROR(F9/G9*1000,"n.a.") -> 19.294596 | I9: =IFERROR(GETPIVOTDATA("Sum of "&I$4,Pivot!$A$3,"Manufacturer",$B9),0) -> 5.901 | J9: =IFERROR(GETPIVOTDATA("Sum of "&J$4,Pivot!$A$3,"Manufacturer",$B9),0) -> 348.1982 | K9: =IFERROR(I9/J9*1000,"n.a.") -> 16.947244 | M9: =IFERROR(F9/C9-1,"n.a.") -> n.a. | N9: =IFERROR(G9/D9-1,"n.a.") -> n.a. | O9: =IFERROR(H9/E9-1,"n.a.") -> n.a.
B10: ArborChemistry | C10: =IFERROR(GETPIVOTDATA("Sum of "&C$4,Pivot!$A$3,"Manufacturer",$B10),0) -> 0.7052 | D10: =IFERROR(GETPIVOTDATA("Sum of "&D$4,Pivot!$A$3,"Manufacturer",$B10),0) -> 47.3253 | E10: =IFERROR(C10/D10*1000,"n.a.") -> 14.901121 | F10: =IFERROR(GETPIVOTDATA("Sum of "&F$4,Pivot!$A$3,"Manufacturer",$B10),0) -> 0 | G10: =IFERROR(GETPIVOTDATA("Sum of "&G$4,Pivot!$A$3,"Manufacturer",$B10),0) -> 0 | H10: =IFERROR(F10/G10*1000,"n.a.") -> n.a. | I10: =IFERROR(GETPIVOTDATA("Sum of "&I$4,Pivot!$A$3,"Manufacturer",$B10),0) -> 0 | J10: =IFERROR(GETPIVOTDATA("Sum of "&J$4,Pivot!$A$3,"Manufacturer",$B10),0) -> 0 | K10: =IFERROR(I10/J10*1000,"n.a.") -> n.a. | M10: =IFERROR(F10/C10-1,"n.a.") -> -1 | N10: =IFERROR(G10/D10-1,"n.a.") -> -1 | O10: =IFERROR(H10/E10-1,"n.a.") -> n.a.
B11: ArkPapers | C11: =IFERROR(GETPIVOTDATA("Sum of "&C$4,Pivot!$A$3,"Manufacturer",$B11),0) -> 104.6661 | D11: =IFERROR(GETPIVOTDATA("Sum of "&D$4,Pivot!$A$3,"Manufacturer",$B11),0) -> 5728.6424 | E11: =IFERROR(C11/D11*1000,"n.a.") -> 18.270664 | F11: =IFERROR(GETPIVOTDATA("Sum of "&F$4,Pivot!$A$3,"Manufacturer",$B11),0) -> 94.425 | G11: =IFERROR(GETPIVOTDATA("Sum of "&G$4,Pivot!$A$3,"Manufacturer",$B11),0) -> 5002.3732 | H11: =IFERROR(F11/G11*1000,"n.a.") -> 18.876041 | I11: =IFERROR(GETPIVOTDATA("Sum of "&I$4,Pivot!$A$3,"Manufacturer",$B11),0) -> 45.9484 | J11: =IFERROR(GETPIVOTDATA("Sum of "&J$4,Pivot!$A$3,"Manufacturer",$B11),0) -> 2228.9191 | K11: =IFERROR(I11/J11*1000,"n.a.") -> 20.614656 | M11: =IFERROR(F11/C11-1,"n.a.") -> -0.097845434 | N11: =IFERROR(G11/D11-1,"n.a.") -> -0.12677859 | O11: =IFERROR(H11/E11-1,"n.a.") -> 0.033133813
B12: Arkana PaperCraft | C12: =IFERROR(GETPIVOTDATA("Sum of "&C$4,Pivot!$A$3,"Manufacturer",$B12),0) -> 1.5393 | D12: =IFERROR(GETPIVOTDATA("Sum of "&D$4,Pivot!$A$3,"Manufacturer",$B12),0) -> 71.3574 | E12: =IFERROR(C12/D12*1000,"n.a.") -> 21.571694 | F12: =IFERROR(GETPIVOTDATA("Sum of "&F$4,Pivot!$A$3,"Manufacturer",$B12),0) -> 2.0579 | G12: =IFERROR(GETPIVOTDATA("Sum of "&G$4,Pivot!$A$3,"Manufacturer",$B12),0) -> 96.8431 | H12: =IFERROR(F12/G12*1000,"n.a.") -> 21.249836 | I12: =IFERROR(GETPIVOTDATA("Sum of "&I$4,Pivot!$A$3,"Manufacturer",$B12),0) -> 0.6821 | J12: =IFERROR(GETPIVOTDATA("Sum of "&J$4,Pivot!$A$3,"Manufacturer",$B12),0) -> 27.711 | K12: =IFERROR(I12/J12*1000,"n.a.") -> 24.614774 | M12: =IFERROR(F12/C12-1,"n.a.") -> 0.33690639 | N12: =IFERROR(G12/D12-1,"n.a.") -> 0.35715567 | O12: =IFERROR(H12/E12-1,"n.a.") -> -0.014920384
B13: Fragrantium S.A. | C13: =IFERROR(GETPIVOTDATA("Sum of "&C$4,Pivot!$A$3,"Manufacturer",$B13),0) -> 0.0445 | D13: =IFERROR(GETPIVOTDATA("Sum of "&D$4,Pivot!$A$3,"Manufacturer",$B13),0) -> 0.3676 | E13: =IFERROR(C13/D13*1000,"n.a.") -> 121.0555 | F13: =IFERROR(GETPIVOTDATA("Sum of "&F$4,Pivot!$A$3,"Manufacturer",$B13),0) -> 0.062 | G13: =IFERROR(GETPIVOTDATA("Sum of "&G$4,Pivot!$A$3,"Manufacturer",$B13),0) -> 0.4838 | H13: =IFERROR(F13/G13*1000,"n.a.") -> 128.15213 | I13: =IFERROR(GETPIVOTDATA("Sum of "&I$4,Pivot!$A$3,"Manufacturer",$B13),0) -> 0 | J13: =IFERROR(GETPIVOTDATA("Sum of "&J$4,Pivot!$A$3,"Manufacturer",$B13),0) -> 0 | K13: =IFERROR(I13/J13*1000,"n.a.") -> n.a. | M13: =IFERROR(F13/C13-1,"n.a.") -> 0.39325843 | N13: =IFERROR(G13/D13-1,"n.a.") -> 0.31610446 | O13: =IFERROR(H13/E13-1,"n.a.") -> 0.05862298
B14: ArsenicChem | C14: =IFERROR(GETPIVOTDATA("Sum of "&C$4,Pivot!$A$3,"Manufacturer",$B14),0) -> 11.9632 | D14: =IFERROR(GETPIVOTDATA("Sum of "&D$4,Pivot!$A$3,"Manufacturer",$B14),0) -> 603.2765 | E14: =IFERROR(C14/D14*1000,"n.a.") -> 19.830376 | F14: =IFERROR(GETPIVOTDATA("Sum of "&F$4,Pivot!$A$3,"Manufacturer",$B14),0) -> 18.1364 | G14: =IFERROR(GETPIVOTDATA("Sum of "&G$4,Pivot!$A$3,"Manufacturer",$B14),0) -> 937.4516 | H14: =IFERROR(F14/G14*1000,"n.a.") -> 19.346492 | I14: =IFERROR(GETPIVOTDATA("Sum of "&I$4,Pivot!$A$3,"Manufacturer",$B14),0) -> 9.0269 | J14: =IFERROR(GETPIVOTDATA("Sum of "&J$4,Pivot!$A$3,"Manufacturer",$B14),0) -> 454.7745 | K14: =IFERROR(I14/J14*1000,"n.a.") -> 19.849178 | M14: =IFERROR(F14/C14-1,"n.a.") -> 0.51601578 | N14: =IFERROR(G14/D14-1,"n.a.") -> 0.55393356 | O14: =IFERROR(H14/E14-1,"n.a.") -> -0.024401159
B15: Creativa Worldwide | C15: =IFERROR(GETPIVOTDATA("Sum of "&C$4,Pivot!$A$3,"Manufacturer",$B15),0) -> 0 | D15: =IFERROR(GETPIVOTDATA("Sum of "&D$4,Pivot!$A$3,"Manufacturer",$B15),0) -> 0 | E15: =IFERROR(C15/D15*1000,"n.a.") -> n.a. | F15: =IFERROR(GETPIVOTDATA("Sum of "&F$4,Pivot!$A$3,"Manufacturer",$B15),0) -> 13.192 | G15: =IFERROR(GETPIVOTDATA("Sum of "&G$4,Pivot!$A$3,"Manufacturer",$B15),0) -> 565.5391 | H15: =IFERROR(F15/G15*1000,"n.a.") -> 23.326415 | I15: =IFERROR(GETPIVOTDATA("Sum of "&I$4,Pivot!$A$3,"Manufacturer",$B15),0) -> 52.8111 | J15: =IFERROR(GETPIVOTDATA("Sum of "&J$4,Pivot!$A$3,"Manufacturer",$B15),0) -> 2091.2261 | K15: =IFERROR(I15/J15*1000,"n.a.") -> 25.253654 | M15: =IFERROR(F15/C15-1,"n.a.") -> n.a. | N15: =IFERROR(G15/D15-1,"n.a.") -> n.a. | O15: =IFERROR(H15/E15-1,"n.a.") -> n.a.
B16: CultureSana | C16: =IFERROR(GETPIVOTDATA("Sum of "&C$4,Pivot!$A$3,"Manufacturer",$B16),0) -> 3.1665 | D16: =IFERROR(GETPIVOTDATA("Sum of "&D$4,Pivot!$A$3,"Manufacturer",$B16),0) -> 65.2032 | E16: =IFERROR(C16/D16*1000,"n.a.") -> 48.563567 | F16: =IFERROR(GETPIVOTDATA("Sum of "&F$4,Pivot!$A$3,"Manufacturer",$B16),0) -> 2.1887 | G16: =IFERROR(GETPIVOTDATA("Sum of "&G$4,Pivot!$A$3,"Manufacturer",$B16),0) -> 50.3704 | H16: =IFERROR(F16/G16*1000,"n.a.") -> 43.452107 | I16: =IFERROR(GETPIVOTDATA("Sum of "&I$4,Pivot!$A$3,"Manufacturer",$B16),0) -> 0.463 | J16: =IFERROR(GETPIVOTDATA("Sum of "&J$4,Pivot!$A$3,"Manufacturer",$B16),0) -> 10.1665 | K16: =IFERROR(I16/J16*1000,"n.a.") -> 45.54173 | M16: =IFERROR(F16/C16-1,"n.a.") -> -0.3087952 | N16: =IFERROR(G16/D16-1,"n.a.") -> -0.22748577 | O16: =IFERROR(H16/E16-1,"n.a.") -> -0.10525299
... B102: GreenIlgaz Group | C102: =IFERROR(GETPIVOTDATA("Sum of "&C$4,Pivot!$A$3,"Manufacturer",$B102),0) -> 1.8397 | D102: =IFERROR(GETPIVOTDATA("Sum of "&D$4,Pivot!$A$3,"Manufacturer",$B102),0) -> 115.4976 | E102: =IFERROR(C102/D102*1000,"n.a.") -> 15.92847 | F102: =IFERROR(GETPIVOTDATA("Sum of "&F$4,Pivot!$A$3,"Manufacturer",$B102),0) -> 4.3616 | G102: =IFERROR(GETPIVOTDATA("Sum of "&G$4,Pivot!$A$3,"Manufacturer",$B102),0) -> 300.4659 | H102: =IFERROR(F102/G102*1000,"n.a.") -> 14.516123 | I102: =IFERROR(GETPIVOTDATA("Sum of "&I$4,Pivot!$A$3,"Manufacturer",$B102),0) -> 0 | J102: =IFERROR(GETPIVOTDATA("Sum of "&J$4,Pivot!$A$3,"Manufacturer",$B102),0) -> 0 | K102: =IFERROR(I102/J102*1000,"n.a.") -> n.a. | M102: =IFERROR(F102/C102-1,"n.a.") -> 1.3708213 | N102: =IFERROR(G102/D102-1,"n.a.") -> 1.6014904 | O102: =IFERROR(H102/E102-1,"n.a.") -> -0.088668053
B103: Total | C103: =SUM(C5:C102) -> 11880.159 | D103: =SUM(D5:D102) -> 470247.93 | E103: =IFERROR(C103/D103*1000,"n.a.") -> 25.263607 | F103: =SUM(F5:F102) -> 12264.847 | G103: =SUM(G5:G102) -> 475047.06 | H103: =IFERROR(F103/G103*1000,"n.a.") -> 25.818173 | I103: =SUM(I5:I102) -> 6590.0513 | J103: =SUM(J5:J102) -> 239949.4 | K103: =IFERROR(I103/J103*1000,"n.a.") -> 27.464338 | M103: =IFERROR(F103/C103-1,"n.a.") -> 0.032380754 | N103: =IFERROR(G103/D103-1,"n.a.") -> 0.010205541 | O103: =IFERROR(H103/E103-1,"n.a.") -> 0.021951189
