Workbook

Sheet Income Statement
B1: Income Statement:
B2: Omega Industries Ltd
B5: USD in million | C5: 45291 | D5: 44926
B7: Revenue | C7: 319662 | D7: 283549
B8: Cost of goods sold (COGS) | C8: -180969 | D8: -169802
B9: Gross profit | C9: =SUM(C7:C8) -> 138693 | D9: =SUM(D7:D8) -> 113747
B11: Payroll expenses | C11: -19281 | D11: -17451
B12: Depreciation expense | C12: -28787 | D12: -24991
B13: SG&A | C13: -85383 | D13: -53312
B14: Operating Profit | C14: =SUM(C9:C13) -> 5242 | D14: =SUM(D9:D13) -> 17993
B16: Interest expense | C16: -495 | D16: -1798
B17: Profit before tax (PBT) | C17: =SUM(C14:C16) -> 4747 | D17: =SUM(D14:D16) -> 16195
B19: Income tax | C19: -633 | D19: -1844
B20: Net Income | C20: =SUM(C17:C19) -> 4114 | D20: =SUM(D17:D19) -> 14351
B23: Other comprehensive income
B24: Actuarial (loss)/profit on pension liabilities | C24: 15 | D24: 12
B25: Unrealized FX loss on pension liabilities | C25: -1 | D25: -3
B26: Other comprehensive income for the year | C26: =SUM(C24:C25) -> 14 | D26: =SUM(D24:D25) -> 9
B27: Total comprehensive income | C27: 4128 | D27: 14360
B30: Notes:
B31: * Dividends paid during the year | C31: 9779
B32: *Purchase of property, plant and equipment | C32: 8623
B33: *Purchase of intangible assets (software and licenses) | C33: 9052

Sheet Balance Sheet
B1: Balance Sheet:
B2: Omega Industries Ltd
C4: Current Year | D4: Previous Year
B5: USD in million | C5: 45291 | D5: 44926 | E5: Net Change
B7: ASSETS
B8: Non-current assets
B9: Property, plant and equipment (NBV) | C9: 109283 | D9: 129447 | E9: =D9+Workings!C6+Workings!C7-'Balance Sheet'!C9 -> 0
B10: Intangible assets | C10: 18118 | D10: 9066 | E10: =C10-D10 -> 9052
B11: Total non-current assets | C11: =SUM(C9:C10) -> 127401 | D11: =SUM(D9:D10) -> 138513 | E11: =C11-D11 -> -11112
B13: Current assets
B14: Inventory | C14: 31398 | D14: 21150 | E14: =C14-D14 -> 10248
B15: Trade receivables | C15: 13743 | D15: 35885 | E15: =C15-D15 -> -22142
B16: Cash and cash equivalents | C16: 3576 | D16: 16813 | E16: =C16-D16 -> -13237
B17: Total current assets | C17: =SUM(C14:C16) -> 48717 | D17: =SUM(D14:D16) -> 73848 | E17: =C17-D17 -> -25131
B18: Total Assets | C18: =C11+C17 -> 176118 | D18: =D11+D17 -> 212361 | E18: =C18-D18 -> -36243
B20: EQUITY AND LIABILITIES
B21: Equity
B22: Share capital | C22: 29337 | D22: 29337 | E22: =D22-C22 -> 0
B23: Retained earnings | C23: 59109 | D23: 64760 | E23: =D23-C23 -> 5651
B24: Total Equity | C24: =SUM(C22:C23) -> 88446 | D24: =SUM(D22:D23) -> 94097 | E24: =C24-D24 -> -5651
B26: Non-current liabilities
B27: Long-term borrowings | C27: 13902 | D27: 15657 | E27: =C27-D27 -> -1755
B28: Pension liabilities | C28: 17718 | D28: 17732 | E28: =C28-D28 -> -14 | F28: Included in Other Comprehensive Income
B29: Total non-current liabilities | C29: =SUM(C27:C28) -> 31620 | D29: =SUM(D27:D28) -> 33389 | E29: =C29-D29 -> -1769
B31: Current liabilities
B32: Short-term borrowings | C32: 21721 | D32: 25813 | E32: =C32-D32 -> -4092
B33: Trade payables | C33: 34331 | D33: 59062 | E33: =C33-D33 -> -24731
B34: Total current liabilities | C34: =SUM(C32:C33) -> 56052 | D34: =SUM(D32:D33) -> 84875 | E34: =C34-D34 -> -28823
B35: Total Liabilities | C35: =C29+C34 -> 87672 | D35: =D29+D34 -> 118264 | E35: =C35-D35 -> -30592
B37: Total equity and liabilities | C37: =C24+C35 -> 176118 | D37: =D24+D35 -> 212361 | E37: =C37-D37 -> -36243
B40: Check! | C40: =C18-C37 -> 0 | D40: =D18-D37 -> 0 | E40: OK

Sheet Statement of Changes in Equity
B1: Statement of Changes in Equity:
B2: Omega Industries Ltd
D4: Registered capital | E4: Retained earnings | F4: Total
B6: Opening balance at 1.1.2022 | D6: 29337 | E6: 50400 | F6: =SUM(D6:E6) -> 79737
B7: Profit for the year | D7: 0 | E7: ='Income Statement'!D20 -> 14351 | F7: =SUM(D7:E7) -> 14351
B8: Other comprehensive income | D8: 0 | E8: ='Income Statement'!D26 -> 9 | F8: =SUM(D8:E8) -> 9
B9: Total comprehensive income | D9: =D7+D8 -> 0 | E9: =E7+E8 -> 14360 | F9: =F7+F8 -> 14360
B10: Closing balance at 31.12.2022 | D10: =D9+D6 -> 29337 | E10: =E9+E6 -> 64760 | F10: =F9+F6 -> 94097
B12: Opening balance at 1.1.2023 | D12: 29337 | E12: 64760 | F12: =SUM(D12:E12) -> 94097
B13: Profit for the year | D13: 0 | E13: ='Income Statement'!C20 -> 4114 | F13: =SUM(D13:E13) -> 4114
B14: Other comprehensive income | D14: 0 | E14: ='Income Statement'!C26 -> 14 | F14: =SUM(D14:E14) -> 14
B15: Total comprehensive income | D15: 0 | E15: =E13+E14 -> 4128 | F15: =SUM(D15:E15) -> 4128
B16: Dividends paid | D16: 0 | E16: =-'Income Statement'!C31 -> -9779 | F16: =SUM(D16:E16) -> -9779
B17: Closing balance at 31.12.2023 | D17: =D12+D15+D16 -> 29337 | E17: =E12+E15+E16 -> 59109 | F17: =F12+F15+F16 -> 88446
B19: Check! | D19: ='Balance Sheet'!C22 -> 29337 | E19: ='Balance Sheet'!C23 -> 59109 | F19: =D19+E19 -> 88446
D20: =D17-D19 -> 0 | E20: =E17-E19 -> 0 | F20: =F17-F19 -> 0

Sheet Workings
B1: Workings:
B2: Omega Industries LTD
B4: PP&E reconciliation
B5: PP&E opening balance | C5: ='Balance Sheet'!D9 -> 129447
B6: Add: PPE purchases | C6: ='Income Statement'!C32 -> 8623
B7: Less: Depreciation | C7: ='Income Statement'!C12 -> -28787
B8: PP&E closing balance | C8: =SUM(C5:C7) -> 109283
C9: ='Balance Sheet'!C9-Workings!C8 -> 0 | D9: Check!
B12: RE reconciliation
B13: Retained earnings at the beginning of the year | C13: ='Balance Sheet'!D23 -> 64760
B14: Add: Net Income | C14: ='Income Statement'!C20 -> 4114
B15: Add: Other comprehensive income | C15: ='Income Statement'!C26 -> 14
B16: Less: Dividends paid | C16: ='Income Statement'!C31 -> 9779
B17: Retained earnings at the end of the year | C17: =C13+C14+C15-C16 -> 59109
C18: ='Balance Sheet'!C23-Workings!C17 -> 0 | D18: Check!

Sheet CFS-Indirect Method
B1: Cash Flow Statement:
B2: Omega Industries Ltd
B3: Indirect Method:
B5: USD in million | C5: 2023
B7: Cash flows from operating activities
B8: Net Income | C8: ='Income Statement'!C20 -> 4114
B9: Add: tax for the year | C9: =-'Income Statement'!C19 -> 633
B10: Add: interest expense | C10: =-'Income Statement'!C16 -> 495
B11: Operating profit | C11: =SUM(C8:C10) -> 5242
B13: Adjustments for non-cash items:
B14: Add: depreciation expense | C14: =-'Income Statement'!C12 -> 28787 | E14: non-cash items
B16: Changes in working capital:
B17: Increase in inventory | C17: =-'Balance Sheet'!E14 -> -10248 | E17: changes in working capital
B18: Decrease in trade receivables | C18: =-'Balance Sheet'!E15 -> 22142
B19: Increase in trade payables | C19: ='Balance Sheet'!E33 -> -24731
C20: =SUM(C17:C19) -> -12837
B22: Cash flow from operations | C22: =SUM(C11:C19) -> 21192
B24: Dividends paid | C24: =-'Income Statement'!C31 -> -9779
B25: Interest paid | C25: ='Income Statement'!C16 -> -495
B26: Tax paid | C26: ='Income Statement'!C19 -> -633
B27: Net cash generated from operating activities | C27: =SUM(C22:C26) -> 10285
B29: Cash flows from investing activities
B30: Purchase of property, plant and equipment | C30: =-'Income Statement'!C32 -> -8623
B31: Purchase of intangible assets | C31: =-'Income Statement'!C33 -> -9052
B32: Net cash used in investing activities | C32: =SUM(C30:C31) -> -17675
B34: Cash flows from financing activities
B35: Issues of share capital | C35: ='Balance Sheet'!E22 -> 0
B36: Long-term borrowings repaid | C36: ='Balance Sheet'!E27 -> -1755
B37: Short-term borrowings repaid | C37: ='Balance Sheet'!E32 -> -4092
B38: Net cash used in financing activities | C38: =SUM(C35:C37) -> -5847
B40: Net cash flow for the period | C40: =C27+C32+C38 -> -13237
B42: Cash and cash equivalents at the beginning of the period | C42: ='Balance Sheet'!D16 -> 16813
B43: Cash and cash equivalents at the end of the period | C43: ='Balance Sheet'!C16 -> 3576
B44: Net increase/decrease in cash | C44: =C43-C42 -> -13237
B46: Check! | C46: =C40-C44 -> 0 | E46: ok
C48: =C49-C50 -> 0
B49: FCFF | C49: =C11+C14+C10*(1-0.2)+SUM(C17:C19)+SUM(C30:C31) -> 3913 | E49: =_xlfn.FORMULATEXT(C49) -> =C11+C14+C10*(1-0.2)+SUM(C17:C19)+SUM(C30:C31)
B50: FCFF | C50: =C22+SUM(C30:C31)+C10*(1-0.2) -> 3913 | E50: =_xlfn.FORMULATEXT(C50) -> =C22+SUM(C30:C31)+C10*(1-0.2)
B52: FCFE | C52: =C22+C32+C38 -> -2330 | E52: =_xlfn.FORMULATEXT(C52) -> =C22+C32+C38
B53: FCFE | C53: =C50+C25*(1-0.2)+C38 -> -2330 | E53: =_xlfn.FORMULATEXT(C53) -> =C50+C25*(1-0.2)+C38
...
