Workbook

Sheet Index
B1: Index
C4: Volkswagen Statements
C5: P&L | D5: -----------> | E5: Click Here
C6: Common Size P&L | D6: -----------> | E6: Click Here
C7: Balance Sheet | D7: -----------> | E7: Click Here
C8: Common Size Balance Sheet | D8: -----------> | E8: Click Here
C9: Cash Flow Statement | D9: -----------> | E9: Click Here
C10: Statement Of Changes In Equity | D10: -----------> | E10: Click Here
C11: Financial Ratios
C12: Activity Ratios | D12: -----------> | E12: Click Here
C13: Liquidity Ratios | D13: -----------> | E13: Click Here
C14: Solvency Ratios | D14: -----------> | E14: Click Here
C15: Profitability Ratios | D15: -----------> | E15: Click Here
C16: Valuation Ratios | D16: -----------> | E16: Click Here
C17: Analysis
C18: Dupont Analysis | D18: -----------> | E18: Click Here
C19: Altman's Credit Score | D19: -----------> | E19: Click Here
C20: Segment Reporting | D20: -----------> | E20: Click Here

Sheet P&L
B1: P&L
B3: € in Millions | C3: 2022 | D3: 2023 | E3: 2024 | F3: 2025 | H3: Var23-22% | I3: Var24-23% | J3: Var25-24%
B4: Revenue | C4: 279050 | D4: 322284 | E4: 324656 | F4: 321913 | H4: =D4/C4-1 -> 0.15493281 | I4: =E4/D4-1 -> 0.0073599682 | J4: =F4/E4-1 -> -0.0084489429
B5: Cost of Goods sold(COGS) | C5: -226866 | D5: -261262 | E5: -265184 | F5: -270671 | H5: =D5/C5-1 -> 0.15161373 | I5: =E5/D5-1 -> 0.015011751 | J5: =F5/E5-1 -> 0.020691294
B6: Gross Profit | C6: 52184 | D6: 61022 | E6: 59472 | F6: 51243 | H6: =D6/C6-1 -> 0.16936226 | I6: =E6/D6-1 -> -0.025400675 | J6: =F6/E6-1 -> -0.13836764
B7: Distribution expenses | C7: -19840 | D7: -21340 | E7: -22320 | F7: -22804 | H7: =D7/C7-1 -> 0.075604839 | I7: =E7/D7-1 -> 0.045923149 | J7: =F7/E7-1 -> 0.021684588
B8: Administrative expenses | C8: -11655 | D8: -12724 | E8: -12754 | F8: -12541 | H8: =D8/C8-1 -> 0.091720292 | I8: =E8/D8-1 -> 0.0023577491 | J8: =F8/E8-1 -> -0.016700643
B9: Other operating income | C9: 19234 | D9: 15152 | E9: 14974 | F9: 13615 | H9: =D9/C9-1 -> -0.21222835 | I9: =E9/D9-1 -> -0.011747624 | J9: =F9/E9-1 -> -0.090757313
B10: Other operating expenses | C10: -17813 | D10: -19534 | E10: -20312 | F10: -20644 | H10: =D10/C10-1 -> 0.096614832 | I10: =E10/D10-1 -> 0.039827992 | J10: =F10/E10-1 -> 0.016345018
B11: Operating Profit | C11: 22109 | D11: 22576 | E11: 19060 | F11: 8868 | H11: =D11/C11-1 -> 0.02112262 | I11: =E11/D11-1 -> -0.15574061 | J11: =F11/E11-1 -> -0.53473242
B12: Share of the result of equity-accounted investments | C12: 2403 | D12: 2291 | E12: 375 | F12: 930 | H12: =D12/C12-1 -> -0.046608406 | I12: =E12/D12-1 -> -0.83631602 | J12: =F12/E12-1 -> 1.48
B13: Interest income | C13: 1325 | D13: 2658 | E13: 2419 | F13: 1824 | H13: =D13/C13-1 -> 1.0060377 | I13: =E13/D13-1 -> -0.089917231 | J13: =F13/E13-1 -> -0.24596941
B14: Interest expenses | C14: -408 | D14: -3592 | E14: -3446 | F14: -3245 | H14: =D14/C14-1 -> 7.8039216 | I14: =E14/D14-1 -> -0.04064588 | J14: =F14/E14-1 -> -0.058328497
B15: Other financial result | C15: -3359 | D15: -739 | E15: -1602 | F15: 930 | H15: =D15/C15-1 -> -0.77999405 | I15: =E15/D15-1 -> 1.1677943 | J15: =F15/E15-1 -> -1.5805243
... B17: Earnings before tax (EBT) | C17: 22070 | D17: 23194 | E17: 16806 | F17: 9307 | H17: =D17/C17-1 -> 0.050928863 | I17: =E17/D17-1 -> -0.27541606 | J17: =F17/E17-1 -> -0.44620969
B18: Income tax income/expense | C18: =SUM(C19:C20) -> -6217 | D18: -5266 | E18: -4411 | F18: -2403 | H18: =D18/C18-1 -> -0.15296767 | I18: =E18/D18-1 -> -0.16236232 | J18: =F18/E18-1 -> -0.45522557
B19: Current | C19: -5263 | D19: -6791 | E19: -5858 | F19: -3837 | H19: =D19/C19-1 -> 0.29032871 | I19: =E19/D19-1 -> -0.13738772 | J19: =F19/E19-1 -> -0.34499829
B20: Deferred | C20: -954 | D20: 1526 | E20: 1447 | F20: 1434 | H20: =D20/C20-1 -> -2.5995807 | I20: =E20/D20-1 -> -0.051769332 | J20: =F20/E20-1 -> -0.008984105
B21: Net Income | C21: 15852 | D21: 17928 | E21: 12394 | F21: 6904 | H21: =D21/C21-1 -> 0.13096139 | I21: =E21/D21-1 -> -0.30867916 | J21: =F21/E21-1 -> -0.44295627
B23: Lease Payments | C23: 1832 | D23: 1986 | E23: 2098 | F23: 2200
B24: Weighted average number of:
B25: Ordinary shares – basic/diluted Shares | C25: 295089818 | D25: 295089818 | E25: 295089818 | F25: 295089818
B26: Preferred shares – basic/diluted Shares | C26: 206205445 | D26: 206205445 | E26: 206205445 | F26: 206205445
B27: Earnings after tax | C27: 15852 | D27: 17928 | E27: 12394 | F27: 6904
B28: Earnings attributable to noncontrolling interests | C28: 395 | D28: 1329 | E28: 1043 | F28: -419
B29: Earnings attributable to Volkswagen AG hybrid capital investors | C29: 576 | D29: 586 | E29: 630 | F29: 650
B30: Earnings attributable to Volkswagen AG shareholders | C30: 14881 | D30: 16013 | E30: 10721 | F30: 6673
B31: of which basic/diluted earnings attributable to ordinary shares | C31: 8753 | D31: 9419 | E31: 6304 | F31: 3921
B32: of which basic/diluted earnings attributable to preferred shares | C32: 6129 | D32: 6594 | E32: 4417 | F32: 2752
B33: Common Share Closing Price | C33: 147.65 | D33: 118.45 | E33: 92.15 | F33: 105.1
B34: Preferred Share Closing Price | C34: 116.42 | D34: 111.8 | E34: 89.04 | F34: 103.55
B35: Market Capitalization | C35: =67.6*1000 -> 67600 | D35: 58000 | E35: 45600 | F35: 52400
B36: Dividend per Common Share | C36: 8.7 | D36: 9 | E36: 6.3 | F36: 5.2
B37: Dividend per Preffered Share | C37: 8.76 | D37: 9.06 | E37: 6.36 | F37: 5.26
B38: Total Common Share Dividends | C38: 2567 | D38: 2656 | E38: 1859 | F38: 1534
B39: Total Preffered Share Dividends | C39: 1806 | D39: 1868 | E39: 1311 | F39: 1085
B40: Total Dividends | C40: =SUM(C38:C39) -> 4373 | D40: =SUM(D38:D39) -> 4524 | E40: =SUM(E38:E39) -> 3170 | F40: =SUM(F38:F39) -> 2619

Sheet Common Size P&L
B1: Common Size P&L
B3: € in Millions | C3: 2022 | D3: 2023 | E3: 2024 | F3: 2025 | H3: Var23-22% | I3: Var24-23% | J3: Var25-24%
B4: Revenue | C4: ='P&L'!C4/'P&L'!$C$4 -> 1 | D4: ='P&L'!D4/'P&L'!$D$4 -> 1 | E4: ='P&L'!E4/'P&L'!$E$4 -> 1 | F4: ='P&L'!F4/'P&L'!$F$4 -> 1 | H4: =D4/C4-1 -> 0 | I4: =E4/D4-1 -> 0 | J4: =F4/E4-1 -> 0
B5: Cost of Goods sold(COGS) | C5: ='P&L'!C5/'P&L'!$C$4 -> -0.81299409 | D5: ='P&L'!D5/'P&L'!$D$4 -> -0.81065768 | E5: ='P&L'!E5/'P&L'!$E$4 -> -0.81681534 | F5: ='P&L'!F5/'P&L'!$F$4 -> -0.84082035 | H5: =D5/C5-1 -> -0.0028738294 | I5: =E5/D5-1 -> 0.007595877 | J5: =F5/E5-1 -> 0.029388539
B6: Gross Profit | C6: ='P&L'!C6/'P&L'!$C$4 -> 0.18700591 | D6: ='P&L'!D6/'P&L'!$D$4 -> 0.18934232 | E6: ='P&L'!E6/'P&L'!$E$4 -> 0.18318466 | F6: ='P&L'!F6/'P&L'!$F$4 -> 0.15918276 | H6: =D6/C6-1 -> 0.012493756 | I6: =E6/D6-1 -> -0.032521288 | J6: =F6/E6-1 -> -0.13102572
B7: Distribution expenses | C7: ='P&L'!C7/'P&L'!$C$4 -> -0.071098369 | D7: ='P&L'!D7/'P&L'!$D$4 -> -0.066214891 | E7: ='P&L'!E7/'P&L'!$E$4 -> -0.068749692 | F7: ='P&L'!F7/'P&L'!$F$4 -> -0.070839016 | H7: =D7/C7-1 -> -0.06868622 | I7: =E7/D7-1 -> 0.038281431 | J7: =F7/E7-1 -> 0.030390297
B8: Administrative expenses | C8: ='P&L'!C8/'P&L'!$C$4 -> -0.041766708 | D8: ='P&L'!D8/'P&L'!$D$4 -> -0.039480706 | E8: ='P&L'!E8/'P&L'!$E$4 -> -0.039284658 | F8: ='P&L'!F8/'P&L'!$F$4 -> -0.038957731 | H8: =D8/C8-1 -> -0.054732635 | I8: =E8/D8-1 -> -0.0049656719 | J8: =F8/E8-1 -> -0.0083220123
B9: Other operating income | C9: ='P&L'!C9/'P&L'!$C$4 -> 0.068926716 | D9: ='P&L'!D9/'P&L'!$D$4 -> 0.047014434 | E9: ='P&L'!E9/'P&L'!$E$4 -> 0.046122665 | F9: ='P&L'!F9/'P&L'!$F$4 -> 0.042294036 | H9: =D9/C9-1 -> -0.31790694 | I9: =E9/D9-1 -> -0.018967989 | J9: =F9/E9-1 -> -0.083009714
B10: Other operating expenses | C10: ='P&L'!C10/'P&L'!$C$4 -> -0.063834438 | D10: ='P&L'!D10/'P&L'!$D$4 -> -0.060611138 | E10: ='P&L'!E10/'P&L'!$E$4 -> -0.062564684 | F10: ='P&L'!F10/'P&L'!$F$4 -> -0.064129128 | H10: =D10/C10-1 -> -0.050494692 | I10: =E10/D10-1 -> 0.032230806 | J10: =F10/E10-1 -> 0.025005228
B11: Operating Profit | C11: ='P&L'!C11/'P&L'!$C$4 -> 0.079229529 | D11: ='P&L'!D11/'P&L'!$D$4 -> 0.070050018 | E11: ='P&L'!E11/'P&L'!$E$4 -> 0.058708294 | F11: ='P&L'!F11/'P&L'!$F$4 -> 0.027547816 | H11: =D11/C11-1 -> -0.11585972 | I11: =E11/D11-1 -> -0.16190893 | J11: =F11/E11-1 -> -0.53076791
B12: Share of the result of equity-accounted investments | C12: ='P&L'!C12/'P&L'!$C$4 -> 0.00861136 | D12: ='P&L'!D12/'P&L'!$D$4 -> 0.0071086371 | E12: ='P&L'!E12/'P&L'!$E$4 -> 0.0011550687 | F12: ='P&L'!F12/'P&L'!$F$4 -> 0.0028889793 | H12: =D12/C12-1 -> -0.17450471 | I12: =E12/D12-1 -> -0.83751193 | J12: =F12/E12-1 -> 1.5011319
B13: Interest income | C13: ='P&L'!C13/'P&L'!$C$4 -> 0.004748253 | D13: ='P&L'!D13/'P&L'!$D$4 -> 0.0082473843 | E13: ='P&L'!E13/'P&L'!$E$4 -> 0.0074509635 | F13: ='P&L'!F13/'P&L'!$F$4 -> 0.0056661272 | H13: =D13/C13-1 -> 0.73693025 | I13: =E13/D13-1 -> -0.096566473 | J13: =F13/E13-1 -> -0.23954436
B14: Interest expenses | C14: ='P&L'!C14/'P&L'!$C$4 -> -0.0014621036 | D14: ='P&L'!D14/'P&L'!$D$4 -> -0.011145449 | E14: ='P&L'!E14/'P&L'!$E$4 -> -0.010614312 | F14: ='P&L'!F14/'P&L'!$F$4 -> -0.010080363 | H14: =D14/C14-1 -> 6.6228864 | I14: =E14/D14-1 -> -0.047655108 | J14: =F14/E14-1 -> -0.050304574
B15: Other financial result | C15: ='P&L'!C15/'P&L'!$C$4 -> -0.012037269 | D15: ='P&L'!D15/'P&L'!$D$4 -> -0.0022930087 | E15: ='P&L'!E15/'P&L'!$E$4 -> -0.0049344537 | F15: ='P&L'!F15/'P&L'!$F$4 -> 0.0028889793 | H15: =D15/C15-1 -> -0.80950757 | I15: =E15/D15-1 -> 1.151956 | J15: =F15/E15-1 -> -1.585471
... B21: Net Income | C21: ='P&L'!C21/'P&L'!$C$4 -> 0.056807024 | D21: ='P&L'!D21/'P&L'!$D$4 -> 0.055627955 | E21: ='P&L'!E21/'P&L'!$E$4 -> 0.038175792 | F21: ='P&L'!F21/'P&L'!$F$4 -> 0.021446788 | H21: =D21/C21-1 -> -0.020755679 | I21: =E21/D21-1 -> -0.31373009 | J21: =F21/E21-1 -> -0.43820974
B23: KPI:
B24: Gross Profit Margin | C24: =C6 -> 0.18700591 | D24: =D6 -> 0.18934232 | E24: =E6 -> 0.18318466 | F24: =F6 -> 0.15918276
B25: Operating Profit Margin | C25: =C11 -> 0.079229529 | D25: =D11 -> 0.070050018 | E25: =E11 -> 0.058708294 | F25: =F11 -> 0.027547816
B26: Net Profit Margin | C26: =C21 -> 0.056807024 | D26: =D21 -> 0.055627955 | E26: =E21 -> 0.038175792 | F26: =F21 -> 0.021446788

Sheet Balance Sheet
B1: Balance Sheet
B3: € in Millions | C3: 2022 | D3: 2023 | E3: 2024 | F3: 2025 | H3: Var23-22% | I3: Var24-23% | J3: Var25-24%
B4: Assets
B5: Non-Current Assets
B6: Intangible assets | C6: 83241 | D6: 89109 | E6: 93333 | F6: 91474 | H6: =D6/C6-1 -> 0.070494107 | I6: =E6/D6-1 -> 0.047402619 | J6: =F6/E6-1 -> -0.019917928
B7: Property, plant and equipment | C7: 63890 | D7: 66880 | E7: 71452 | F7: 73076 | H7: =D7/C7-1 -> 0.046799186 | I7: =E7/D7-1 -> 0.068361244 | J7: =F7/E7-1 -> 0.022728545
B8: Lease assets | C8: 59380 | D8: 64094 | E8: 73193 | F8: 82486 | H8: =D8/C8-1 -> 0.079386999 | I8: =E8/D8-1 -> 0.14196337 | J8: =F8/E8-1 -> 0.12696569
B9: Investment property | C9: 610 | D9: 632 | E9: 622 | F9: 609 | H9: =D9/C9-1 -> 0.036065574 | I9: =E9/D9-1 -> -0.015822785 | J9: =F9/E9-1 -> -0.020900322
B10: Equity-accounted investments | C10: 12668 | D10: 12239 | E10: 10269 | F10: 9996 | H10: =D10/C10-1 -> -0.033864856 | I10: =E10/D10-1 -> -0.16096086 | J10: =F10/E10-1 -> -0.026584867
B11: Other equity investments | C11: 3489 | D11: 4431 | E11: 5731 | F11: 7366 | H11: =D11/C11-1 -> 0.2699914 | I11: =E11/D11-1 -> 0.2933875 | J11: =F11/E11-1 -> 0.28529053
B12: Financial services receivables | C12: 86944 | D12: 94474 | E12: 101087 | F12: 101230 | H12: =D12/C12-1 -> 0.086607471 | I12: =E12/D12-1 -> 0.069998095 | J12: =F12/E12-1 -> 0.001414623
B13: Other financial assets | C13: 13832 | D13: 11757 | E13: 12129 | F13: 11692 | H13: =D13/C13-1 -> -0.15001446 | I13: =E13/D13-1 -> 0.031640725 | J13: =F13/E13-1 -> -0.036029351
B14: Other receivables | C14: 2477 | D14: 2702 | E14: 2868 | F14: 3651 | H14: =D14/C14-1 -> 0.090835688 | I14: =E14/D14-1 -> 0.061435973 | J14: =F14/E14-1 -> 0.27301255
B15: Tax receivables | C15: 394 | D15: 437 | E15: 409 | F15: 411 | H15: =D15/C15-1 -> 0.10913706 | I15: =E15/D15-1 -> -0.064073227 | J15: =F15/E15-1 -> 0.0048899756
B16: Deferred tax assets | C16: 12929 | D16: 13940 | E16: 16581 | F16: 14611 | H16: =D16/C16-1 -> 0.078196303 | I16: =E16/D16-1 -> 0.18945481 | J16: =F16/E16-1 -> -0.11881069
B17: Total Non-Current Assets | C17: 339853 | D17: 360694 | E17: 387674 | F17: 396602 | H17: =D17/C17-1 -> 0.061323572 | I17: =E17/D17-1 -> 0.074800246 | J17: =F17/E17-1 -> 0.023029659
B19: Current assets
B20: Inventories | C20: 52274 | D20: 53601 | E20: 56720 | F20: 56042 | H20: =D20/C20-1 -> 0.025385469 | I20: =E20/D20-1 -> 0.058189213 | J20: =F20/E20-1 -> -0.011953456
B21: Trade receivables | C21: 18534 | D21: 21849 | E21: 21130 | F21: 20760 | H21: =D21/C21-1 -> 0.17886047 | I21: =E21/D21-1 -> -0.032907685 | J21: =F21/E21-1 -> -0.017510648
B22: Financial services receivables | C22: 61549 | D22: 66381 | E22: 68855 | F22: 70026 | H22: =D22/C22-1 -> 0.078506556 | I22: =E22/D22-1 -> 0.037269701 | J22: =F22/E22-1 -> 0.017006753
B23: Other financial assets | C23: 15148 | D23: 16953 | E23: 18649 | F23: 20158 | H23: =D23/C23-1 -> 0.11915764 | I23: =E23/D23-1 -> 0.10004129 | J23: =F23/E23-1 -> 0.080915867
B24: Other receivables | C24: 7813 | D24: 8799 | E24: 10217 | F24: 9881 | H24: =D24/C24-1 -> 0.12619992 | I24: =E24/D24-1 -> 0.16115468 | J24: =F24/E24-1 -> -0.032886366
B25: Tax receivables | C25: 1732 | D25: 1649 | E25: 2038 | F25: 2674 | H25: =D25/C25-1 -> -0.047921478 | I25: =E25/D25-1 -> 0.23590055 | J25: =F25/E25-1 -> 0.31207066
B26: Marketable securities and time deposits | C26: 37206 | D26: 26772 | E26: 27326 | F26: 29522 | H26: =D26/C26-1 -> -0.28043864 | I26: =E26/D26-1 -> 0.020693262 | J26: =F26/E26-1 -> 0.080363024
B27: Cash and cash equivalents | C27: 29172 | D27: 43449 | E27: 40296 | F27: 38801 | H27: =D27/C27-1 -> 0.48940765 | I27: =E27/D27-1 -> -0.072567838 | J27: =F27/E27-1 -> -0.037100457
B28: Assets held for sale | C28: 733 | D28: 190 | E28: - | F28: - | H28: =D28/C28-1 -> -0.74079127 | I28: - | J28: -
B29: Total Current assets | C29: 224159 | D29: 239644 | E29: 245231 | F29: 247865 | H29: =D29/C29-1 -> 0.06908043 | I29: =E29/D29-1 -> 0.023313749 | J29: =F29/E29-1 -> 0.010740893
B31: Total assets | C31: 564013 | D31: 600338 | E31: 632905 | F31: 644467 | H31: =D31/C31-1 -> 0.064404544 | I31: =E31/D31-1 -> 0.054247774 | J31: =F31/E31-1 -> 0.018268145
B33: € in Millions | C33: 2022 | D33: 2023 | E33: 2024 | F33: 2025
B34: Equity and liabilities
B35: Equity
B36: Subscribed capital | C36: 1283 | D36: 1283 | E36: 1283 | F36: 1283 | H36: =D36/C36-1 -> 0 | I36: =E36/D36-1 -> 0 | J36: =F36/E36-1 -> 0
B37: Capital reserve | C37: 14551 | D37: 14551 | E37: 14551 | F37: 14551 | H37: =D37/C37-1 -> 0 | I37: =E37/D37-1 -> 0 | J37: =F37/E37-1 -> 0
B38: Retained earnings | C38: 137272 | D38: 147830 | E38: 155130 | F38: 161357 | H38: =D38/C38-1 -> 0.07691299 | I38: =E38/D38-1 -> 0.049381046 | J38: =F38/E38-1 -> 0.040140527
B39: Other reserves | C39: -1851 | D39: -3125 | E39: -2560 | F39: -3190 | H39: =D39/C39-1 -> 0.68827661 | I39: =E39/D39-1 -> -0.1808 | J39: =F39/E39-1 -> 0.24609375
B40: Equity attributable to Volkswagen AG hybrid capital investors | C40: 14121 | D40: 15155 | E40: 13890 | F40: 14275 | H40: =D40/C40-1 -> 0.073224276 | I40: =E40/D40-1 -> -0.083470802 | J40: =F40/E40-1 -> 0.027717783
B41: Equity attributable to Volkswagen AG shareholders and hybrid capital investors | C41: 165376 | D41: 175694 | E41: 182294 | F41: 188277 | H41: =D41/C41-1 -> 0.062391157 | I41: =E41/D41-1 -> 0.037565312 | J41: =F41/E41-1 -> 0.032820608
B42: Noncontrolling interests | C42: 12952 | D42: 14218 | E42: 14437 | F42: 14777 | H42: =D42/C42-1 -> 0.097745522 | I42: =E42/D42-1 -> 0.01540301 | J42: =F42/E42-1 -> 0.023550599
B43: Total Equity | C43: 178328 | D43: 189912 | E43: 196731 | F43: 203054 | H43: =D43/C43-1 -> 0.064958952 | I43: =E43/D43-1 -> 0.035906104 | J43: =F43/E43-1 -> 0.032140334
B45: Noncurrent liabilities
...

Sheet Common Size Balance Sheet 
B1: Common Size Balance Sheet
B3: € in Millions | C3: 2022 | D3: 2023 | E3: 2024 | F3: 2025 | H3: Var23-22% | I3: Var24-23% | J3: Var25-24%
B4: Assets
B5: Non-Current Assets
B6: Intangible assets | C6: ='Balance Sheet'!C6/'Balance Sheet'!$C$31 -> 0.14758702 | D6: ='Balance Sheet'!D6/'Balance Sheet'!$D$31 -> 0.14843138 | E6: ='Balance Sheet'!E6/'Balance Sheet'!$E$31 -> 0.14746763 | F6: ='Balance Sheet'!F6/'Balance Sheet'!$F$31 -> 0.14193745 | H6: =D6/C6-1 -> 0.0057210988 | I6: =E6/D6-1 -> -0.0064929276 | J6: =F6/E6-1 -> -0.037500999
B7: Property, plant and equipment | C7: ='Balance Sheet'!C7/'Balance Sheet'!$C$31 -> 0.11327753 | D7: ='Balance Sheet'!D7/'Balance Sheet'!$D$31 -> 0.11140391 | E7: ='Balance Sheet'!E7/'Balance Sheet'!$E$31 -> 0.1128953 | F7: ='Balance Sheet'!F7/'Balance Sheet'!$F$31 -> 0.11338982 | H7: =D7/C7-1 -> -0.0165401 | I7: =E7/D7-1 -> 0.013387242 | J7: =F7/E7-1 -> 0.0043803791
B8: Lease assets | C8: ='Balance Sheet'!C8/'Balance Sheet'!$C$31 -> 0.10528126 | D8: ='Balance Sheet'!D8/'Balance Sheet'!$D$31 -> 0.10676319 | E8: ='Balance Sheet'!E8/'Balance Sheet'!$E$31 -> 0.11564611 | F8: ='Balance Sheet'!F8/'Balance Sheet'!$F$31 -> 0.12799104 | H8: =D8/C8-1 -> 0.014075903 | I8: =E8/D8-1 -> 0.083202066 | J8: =F8/E8-1 -> 0.10674747
B9: Investment property | C9: ='Balance Sheet'!C9/'Balance Sheet'!$C$31 -> 0.0010815354 | D9: ='Balance Sheet'!D9/'Balance Sheet'!$D$31 -> 0.0010527403 | E9: ='Balance Sheet'!E9/'Balance Sheet'!$E$31 -> 0.00098276993 | F9: ='Balance Sheet'!F9/'Balance Sheet'!$F$31 -> 0.00094496693 | H9: =D9/C9-1 -> -0.026624248 | I9: =E9/D9-1 -> -0.066464981 | J9: =F9/E9-1 -> -0.038465768
B10: Equity-accounted investments | C10: ='Balance Sheet'!C10/'Balance Sheet'!$C$31 -> 0.022460475 | D10: ='Balance Sheet'!D10/'Balance Sheet'!$D$31 -> 0.020386849 | E10: ='Balance Sheet'!E10/'Balance Sheet'!$E$31 -> 0.016225184 | F10: ='Balance Sheet'!F10/'Balance Sheet'!$F$31 -> 0.015510492 | H10: =D10/C10-1 -> -0.092323357 | I10: =E10/D10-1 -> -0.20413478 | J10: =F10/E10-1 -> -0.04404833
B11: Other equity investments | C11: ='Balance Sheet'!C11/'Balance Sheet'!$C$31 -> 0.0061860276 | D11: ='Balance Sheet'!D11/'Balance Sheet'!$D$31 -> 0.0073808421 | E11: ='Balance Sheet'!E11/'Balance Sheet'!$E$31 -> 0.0090550715 | F11: ='Balance Sheet'!F11/'Balance Sheet'!$F$31 -> 0.0114296 | H11: =D11/C11-1 -> 0.19314729 | I11: =E11/D11-1 -> 0.22683446 | J11: =F11/E11-1 -> 0.26223189
B12: Financial services receivables | C12: ='Balance Sheet'!C12/'Balance Sheet'!$C$31 -> 0.15415248 | D12: ='Balance Sheet'!D12/'Balance Sheet'!$D$31 -> 0.15736802 | E12: ='Balance Sheet'!E12/'Balance Sheet'!$E$31 -> 0.15971907 | F12: ='Balance Sheet'!F12/'Balance Sheet'!$F$31 -> 0.15707554 | H12: =D12/C12-1 -> 0.020859482 | I12: =E12/D12-1 -> 0.014939866 | J12: =F12/E12-1 -> -0.016551162
B13: Other financial assets | C13: ='Balance Sheet'!C13/'Balance Sheet'!$C$31 -> 0.024524257 | D13: ='Balance Sheet'!D13/'Balance Sheet'!$D$31 -> 0.019583968 | E13: ='Balance Sheet'!E13/'Balance Sheet'!$E$31 -> 0.019164014 | F13: ='Balance Sheet'!F13/'Balance Sheet'!$F$31 -> 0.018142124 | H13: =D13/C13-1 -> -0.20144503 | I13: =E13/D13-1 -> -0.021443772 | J13: =F13/E13-1 -> -0.053323377
B14: Other receivables | C14: ='Balance Sheet'!C14/'Balance Sheet'!$C$31 -> 0.0043917427 | D14: ='Balance Sheet'!D14/'Balance Sheet'!$D$31 -> 0.0045007979 | E14: ='Balance Sheet'!E14/'Balance Sheet'!$E$31 -> 0.0045314858 | F14: ='Balance Sheet'!F14/'Balance Sheet'!$F$31 -> 0.0056651465 | H14: =D14/C14-1 -> 0.02483186 | I14: =E14/D14-1 -> 0.0068183209 | J14: =F14/E14-1 -> 0.25017419
B15: Tax receivables | C15: ='Balance Sheet'!C15/'Balance Sheet'!$C$31 -> 0.00069856546 | D15: ='Balance Sheet'!D15/'Balance Sheet'!$D$31 -> 0.00072792327 | E15: ='Balance Sheet'!E15/'Balance Sheet'!$E$31 -> 0.00064622653 | F15: ='Balance Sheet'!F15/'Balance Sheet'!$F$31 -> 0.0006377363 | H15: =D15/C15-1 -> 0.042025856 | I15: =E15/D15-1 -> -0.11223263 | J15: =F15/E15-1 -> -0.013138159
B16: Deferred tax assets | C16: ='Balance Sheet'!C16/'Balance Sheet'!$C$31 -> 0.02292323 | D16: ='Balance Sheet'!D16/'Balance Sheet'!$D$31 -> 0.023220253 | E16: ='Balance Sheet'!E16/'Balance Sheet'!$E$31 -> 0.026198245 | F16: ='Balance Sheet'!F16/'Balance Sheet'!$F$31 -> 0.022671448 | H16: =D16/C16-1 -> 0.012957253 | I16: =E16/D16-1 -> 0.12824977 | J16: =F16/E16-1 -> -0.13461958
B17: Total Non-Current Assets | C17: ='Balance Sheet'!C17/'Balance Sheet'!$C$31 -> 0.60256235 | D17: ='Balance Sheet'!D17/'Balance Sheet'!$D$31 -> 0.60081821 | E17: ='Balance Sheet'!E17/'Balance Sheet'!$E$31 -> 0.61253111 | F17: ='Balance Sheet'!F17/'Balance Sheet'!$F$31 -> 0.61539536 | H17: =D17/C17-1 -> -0.0028945495 | I17: =E17/D17-1 -> 0.019494917 | J17: =F17/E17-1 -> 0.0046760909
B19: Current assets
B20: Inventories | C20: ='Balance Sheet'!C20/'Balance Sheet'!$C$31 -> 0.092682261 | D20: ='Balance Sheet'!D20/'Balance Sheet'!$D$31 -> 0.089284703 | E20: ='Balance Sheet'!E20/'Balance Sheet'!$E$31 -> 0.089618505 | F20: ='Balance Sheet'!F20/'Balance Sheet'!$F$31 -> 0.086958681 | H20: =D20/C20-1 -> -0.036658125 | I20: =E20/D20-1 -> 0.0037386269 | J20: =F20/E20-1 -> -0.029679412
B21: Trade receivables | C21: ='Balance Sheet'!C21/'Balance Sheet'!$C$31 -> 0.032860945 | D21: ='Balance Sheet'!D21/'Balance Sheet'!$D$31 -> 0.036394498 | E21: ='Balance Sheet'!E21/'Balance Sheet'!$E$31 -> 0.033385737 | F21: ='Balance Sheet'!F21/'Balance Sheet'!$F$31 -> 0.032212666 | H21: =D21/C21-1 -> 0.10753048 | I21: =E21/D21-1 -> -0.082670754 | J21: =F21/E21-1 -> -0.035136907
B22: Financial services receivables | C22: ='Balance Sheet'!C22/'Balance Sheet'!$C$31 -> 0.10912692 | D22: ='Balance Sheet'!D22/'Balance Sheet'!$D$31 -> 0.11057271 | E22: ='Balance Sheet'!E22/'Balance Sheet'!$E$31 -> 0.108792 | F22: ='Balance Sheet'!F22/'Balance Sheet'!$F$31 -> 0.10865723 | H22: =D22/C22-1 -> 0.013248733 | I22: =E22/D22-1 -> -0.016104443 | J22: =F22/E22-1 -> -0.0012387613
B23: Other financial assets | C23: ='Balance Sheet'!C23/'Balance Sheet'!$C$31 -> 0.026857537 | D23: ='Balance Sheet'!D23/'Balance Sheet'!$D$31 -> 0.028239092 | E23: ='Balance Sheet'!E23/'Balance Sheet'!$E$31 -> 0.029465718 | F23: ='Balance Sheet'!F23/'Balance Sheet'!$F$31 -> 0.03127856 | H23: =D23/C23-1 -> 0.051440123 | I23: =E23/D23-1 -> 0.043437148 | J23: =F23/E23-1 -> 0.061523797
B24: Other receivables | C24: ='Balance Sheet'!C24/'Balance Sheet'!$C$31 -> 0.013852518 | D24: ='Balance Sheet'!D24/'Balance Sheet'!$D$31 -> 0.014656743 | E24: ='Balance Sheet'!E24/'Balance Sheet'!$E$31 -> 0.016143023 | F24: ='Balance Sheet'!F24/'Balance Sheet'!$F$31 -> 0.01533205 | H24: =D24/C24-1 -> 0.05805629 | I24: =E24/D24-1 -> 0.10140586 | J24: =F24/E24-1 -> -0.050236778
B25: Tax receivables | C25: ='Balance Sheet'!C25/'Balance Sheet'!$C$31 -> 0.0030708512 | D25: ='Balance Sheet'!D25/'Balance Sheet'!$D$31 -> 0.002746786 | E25: ='Balance Sheet'!E25/'Balance Sheet'!$E$31 -> 0.0032200725 | F25: ='Balance Sheet'!F25/'Balance Sheet'!$F$31 -> 0.0041491651 | H25: =D25/C25-1 -> -0.10552945 | I25: =E25/D25-1 -> 0.17230558 | J25: =F25/E25-1 -> 0.28853158
B26: Marketable securities and time deposits | C26: ='Balance Sheet'!C26/'Balance Sheet'!$C$31 -> 0.065966565 | D26: ='Balance Sheet'!D26/'Balance Sheet'!$D$31 -> 0.044594878 | E26: ='Balance Sheet'!E26/'Balance Sheet'!$E$31 -> 0.043175516 | F26: ='Balance Sheet'!F26/'Balance Sheet'!$F$31 -> 0.045808397 | H26: =D26/C26-1 -> -0.32397756 | I26: =E26/D26-1 -> -0.031827918 | J26: =F26/E26-1 -> 0.060980872
B27: Cash and cash equivalents | C27: ='Balance Sheet'!C27/'Balance Sheet'!$C$31 -> 0.051722212 | D27: ='Balance Sheet'!D27/'Balance Sheet'!$D$31 -> 0.072374229 | E27: ='Balance Sheet'!E27/'Balance Sheet'!$E$31 -> 0.063668323 | F27: ='Balance Sheet'!F27/'Balance Sheet'!$F$31 -> 0.060206341 | H27: =D27/C27-1 -> 0.3992872 | I27: =E27/D27-1 -> -0.12029014 | J27: =F27/E27-1 -> -0.054375266
B28: Assets held for sale | C28: ='Balance Sheet'!C28/'Balance Sheet'!$C$31 -> 0.0012996154 | D28: ='Balance Sheet'!D28/'Balance Sheet'!$D$31 -> 0.00031648838 | E28: - | F28: - | H28: =D28/C28-1 -> -0.75647536 | I28: - | J28: -
B29: Total Current assets | C29: ='Balance Sheet'!C29/'Balance Sheet'!$C$31 -> 0.39743587 | D29: ='Balance Sheet'!D29/'Balance Sheet'!$D$31 -> 0.39918179 | E29: ='Balance Sheet'!E29/'Balance Sheet'!$E$31 -> 0.38746889 | F29: ='Balance Sheet'!F29/'Balance Sheet'!$F$31 -> 0.38460464 | H29: =D29/C29-1 -> 0.0043929591 | I29: =E29/D29-1 -> -0.029342272 | J29: =F29/E29-1 -> -0.0073922093
B31: Total assets | C31: ='Balance Sheet'!C31/'Balance Sheet'!$C$31 -> 1 | D31: ='Balance Sheet'!D31/'Balance Sheet'!$D$31 -> 1 | E31: ='Balance Sheet'!E31/'Balance Sheet'!$E$31 -> 1 | F31: ='Balance Sheet'!F31/'Balance Sheet'!$F$31 -> 1 | H31: =D31/C31-1 -> 0 | I31: =E31/D31-1 -> 0 | J31: =F31/E31-1 -> 0
B33: € in Millions
B34: Equity and liabilities
B35: Equity
B36: Subscribed capital | C36: ='Balance Sheet'!C36/'Balance Sheet'!$C$31 -> 0.0022747703 | D36: ='Balance Sheet'!D36/'Balance Sheet'!$D$31 -> 0.0021371294 | E36: ='Balance Sheet'!E36/'Balance Sheet'!$E$31 -> 0.0020271605 | F36: ='Balance Sheet'!F36/'Balance Sheet'!$F$31 -> 0.0019907924 | H36: =D36/C36-1 -> -0.060507581 | I36: =E36/D36-1 -> -0.05145638 | J36: =F36/E36-1 -> -0.017940407
B37: Capital reserve | C37: ='Balance Sheet'!C37/'Balance Sheet'!$C$31 -> 0.025799051 | D37: ='Balance Sheet'!D37/'Balance Sheet'!$D$31 -> 0.024238013 | E37: ='Balance Sheet'!E37/'Balance Sheet'!$E$31 -> 0.022990812 | F37: ='Balance Sheet'!F37/'Balance Sheet'!$F$31 -> 0.022578348 | H37: =D37/C37-1 -> -0.060507581 | I37: =E37/D37-1 -> -0.05145638 | J37: =F37/E37-1 -> -0.017940407
B38: Retained earnings | C38: ='Balance Sheet'!C38/'Balance Sheet'!$C$31 -> 0.24338446 | D38: ='Balance Sheet'!D38/'Balance Sheet'!$D$31 -> 0.24624462 | E38: ='Balance Sheet'!E38/'Balance Sheet'!$E$31 -> 0.24510788 | F38: ='Balance Sheet'!F38/'Balance Sheet'!$F$31 -> 0.25037279 | H38: =D38/C38-1 -> 0.011751591 | I38: =E38/D38-1 -> -0.0046163038 | J38: =F38/E38-1 -> 0.021479983
B39: Other reserves | C39: ='Balance Sheet'!C39/'Balance Sheet'!$C$31 -> -0.0032818392 | D39: ='Balance Sheet'!D39/'Balance Sheet'!$D$31 -> -0.005205401 | E39: ='Balance Sheet'!E39/'Balance Sheet'!$E$31 -> -0.0040448409 | F39: ='Balance Sheet'!F39/'Balance Sheet'!$F$31 -> -0.0049498268 | H39: =D39/C39-1 -> 0.58612307 | I39: =E39/D39-1 -> -0.22295307 | J39: =F39/E39-1 -> 0.22373832
B40: Equity attributable to Volkswagen AG hybrid capital investors | C40: ='Balance Sheet'!C40/'Balance Sheet'!$C$31 -> 0.025036657 | D40: ='Balance Sheet'!D40/'Balance Sheet'!$D$31 -> 0.025244112 | E40: ='Balance Sheet'!E40/'Balance Sheet'!$E$31 -> 0.021946422 | F40: ='Balance Sheet'!F40/'Balance Sheet'!$F$31 -> 0.022150087 | H40: =D40/C40-1 -> 0.0082860714 | I40: =E40/D40-1 -> -0.13063208 | J40: =F40/E40-1 -> 0.0092801077
B41: Equity attributable to Volkswagen AG shareholders and hybrid capital investors | C41: ='Balance Sheet'!C41/'Balance Sheet'!$C$31 -> 0.2932131 | D41: ='Balance Sheet'!D41/'Balance Sheet'!$D$31 -> 0.29265847 | E41: ='Balance Sheet'!E41/'Balance Sheet'!$E$31 -> 0.28802743 | F41: ='Balance Sheet'!F41/'Balance Sheet'!$F$31 -> 0.29214374 | H41: =D41/C41-1 -> -0.0018915616 | I41: =E41/D41-1 -> -0.015824042 | J41: =F41/E41-1 -> 0.014291387
B42: Noncontrolling interests | C42: ='Balance Sheet'!C42/'Balance Sheet'!$C$31 -> 0.02296401 | D42: ='Balance Sheet'!D42/'Balance Sheet'!$D$31 -> 0.023683325 | E42: ='Balance Sheet'!E42/'Balance Sheet'!$E$31 -> 0.02281069 | F42: ='Balance Sheet'!F42/'Balance Sheet'!$F$31 -> 0.022929025 | H42: =D42/C42-1 -> 0.031323596 | I42: =E42/D42-1 -> -0.036845953 | J42: =F42/E42-1 -> 0.0051876853
B43: Total Equity | C43: ='Balance Sheet'!C43/'Balance Sheet'!$C$31 -> 0.31617711 | D43: ='Balance Sheet'!D43/'Balance Sheet'!$D$31 -> 0.31634179 | E43: ='Balance Sheet'!E43/'Balance Sheet'!$E$31 -> 0.31083812 | F43: ='Balance Sheet'!F43/'Balance Sheet'!$F$31 -> 0.31507277 | H43: =D43/C43-1 -> 0.00052086228 | I43: =E43/D43-1 -> -0.017397874 | J43: =F43/E43-1 -> 0.013623317
B45: Noncurrent liabilities
...

Sheet Cash Flow Statement
B1: Cash Flow Statement
B3: € in Millions | C3: 2022 | D3: 2023 | E3: 2024 | F3: 2025 | H3: Var23-22% | I3: Var24-23% | J3: Var25-24%
B4: Cash and cash equivalents at beginning of period | C4: 39123 | D4: 29738 | E4: 43522 | F4: 40296 | H4: =D4/C4-1 -> -0.23988447 | I4: =E4/D4-1 -> 0.4635147 | J4: =F4/E4-1 -> -0.074123432
B5: Earnings before tax | C5: 22070 | D5: 23194 | E5: 16806 | F5: 9307 | H5: =D5/C5-1 -> 0.050928863 | I5: =E5/D5-1 -> -0.27541606 | J5: =F5/E5-1 -> -0.44620969
B6: Income taxes paid | C6: -4416 | D6: -7716 | E6: -6187 | F6: -5152 | H6: =D6/C6-1 -> 0.74728261 | I6: =E6/D6-1 -> -0.19815967 | J6: =F6/E6-1 -> -0.16728625
B7: Depreciation and amortization of, and impairment losses on, intangible assets, property, plant and equipment,and Investment Property | C7: 13364 | D7: 11727 | E7: 12858 | F7: 16866 | H7: =D7/C7-1 -> -0.12249327 | I7: =E7/D7-1 -> 0.096444103 | J7: =F7/E7-1 -> 0.31171255
B8: Amortization of and impairment losses on capitalized development costs | C8: 5144 | D8: 5184 | E8: 7209 | F8: 8365 | H8: =D8/C8-1 -> 0.0077760498 | I8: =E8/D8-1 -> 0.390625 | J8: =F8/E8-1 -> 0.16035511
B9: Impairment losses on equity investments | C9: 2185 | D9: 717 | E9: 710 | F9: 38 | H9: =D9/C9-1 -> -0.67185355 | I9: =E9/D9-1 -> -0.009762901 | J9: =F9/E9-1 -> -0.94647887
B10: Depreciation of and impairment losses on lease assets | C10: 9977 | D10: 10655 | E10: 11279 | F10: 12203 | H10: =D10/C10-1 -> 0.067956299 | I10: =E10/D10-1 -> 0.058564054 | J10: =F10/E10-1 -> 0.081922156
B11: Gain/loss on disposal of noncurrent assets and equity investments | C11: 30 | D11: 208 | E11: 110 | F11: -95 | H11: =D11/C11-1 -> 5.9333333 | I11: =E11/D11-1 -> -0.47115385 | J11: =F11/E11-1 -> -1.8636364
B12: Share of the result of equity-accounted investments | C12: 568 | D12: 271 | E12: 2362 | F12: 968 | H12: =D12/C12-1 -> -0.52288732 | I12: =E12/D12-1 -> 7.7158672 | J12: =F12/E12-1 -> -0.59017782
B13: Other non-cash expense/income | C13: -539 | D13: 3953 | E13: 903 | F13: -946 | H13: =D13/C13-1 -> -8.3339518 | I13: =E13/D13-1 -> -0.7715659 | J13: =F13/E13-1 -> -2.047619
B14: Change in inventories | C14: -8385 | D14: -2071 | E14: -2695 | F14: -896 | H14: =D14/C14-1 -> -0.75301133 | I14: =E14/D14-1 -> 0.30130372 | J14: =F14/E14-1 -> -0.66753247
B15: Change in receivables (excluding financial services) | C15: -3065 | D15: -4361 | E15: -2083 | F15: -211 | H15: =D15/C15-1 -> 0.4228385 | I15: =E15/D15-1 -> -0.52235726 | J15: =F15/E15-1 -> -0.89870379
... B32: Dividends paid | C32: -4362 | D32: -11732 | E32: -5779 | F32: -4460 | H32: =D32/C32-1 -> 1.6895919 | I32: =E32/D32-1 -> -0.50741562 | J32: =F32/E32-1 -> -0.22824018
B33: Capital transactions with noncontrolling interest shareholders | C33: 16198 | D33: -8 | E33: - | F33: 352 | H33: =D33/C33-1 -> -1.0004939 | I33: - | J33: -
B34: Proceeds from issuance of bonds | C34: 23876 | D34: 37740 | E34: 38420 | F34: 35993 | H34: =D34/C34-1 -> 0.58066678 | I34: =E34/D34-1 -> 0.018018018 | J34: =F34/E34-1 -> -0.063170224
B35: Repayments of bonds | C35: -25638 | D35: -32582 | E35: -32617 | F35: -32669 | H35: =D35/C35-1 -> 0.27084796 | I35: =E35/D35-1 -> 0.0010742128 | J35: =F35/E35-1 -> 0.0015942607
B36: Proceeds from issuance of commercial paper and notes | C36: - | D36: - | E36: 13828 | F36: 27549 | H36: - | I36: - | J36: =F36/E36-1 -> 0.99226208
B37: Repayments of commercial paper and notes | C37: - | D37: - | E37: -12414 | F37: -30417 | H37: - | I37: - | J37: =F37/E37-1 -> 1.4502175
B38: Changes in other financial liabilities | C38: -4366 | D38: 22776 | E38: 12179 | F38: 16624 | H38: =D38/C38-1 -> -6.2166743 | I38: =E38/D38-1 -> -0.46527046 | J38: =F38/E38-1 -> 0.36497249
B39: Repayments of lease liabilities | C39: -1248 | D39: -1190 | E39: -1334 | F39: -1476 | H39: =D39/C39-1 -> -0.046474359 | I39: =E39/D39-1 -> 0.1210084 | J39: =F39/E39-1 -> 0.10644678
B40: Cash flows from financing activities | C40: 4225 | D40: 16008 | E40: 11140 | F40: 11918 | H40: =D40/C40-1 -> 2.7888757 | I40: =E40/D40-1 -> -0.30409795 | J40: =F40/E40-1 -> 0.06983842
B41: Effect of exchange rate changes on cash and cash equivalents | C41: -285 | D41: -1764 | E41: 55 | F41: -938 | H41: =D41/C41-1 -> 5.1894737 | I41: =E41/D41-1 -> -1.0311791 | J41: =F41/E41-1 -> -18.054545
B42: Change of loss allowance within cash and cash equivalents | C42: 1 | D42: -2 | E42: 1 | F42: 0 | H42: =D42/C42-1 -> -3 | I42: =E42/D42-1 -> -1.5 | J42: =F42/E42-1 -> -1
B43: Net change in cash and cash equivalents | C43: -9385 | D43: 13785 | E43: -3226 | F43: -1495 | H43: =D43/C43-1 -> -2.4688332 | I43: =E43/D43-1 -> -1.2340225 | J43: =F43/E43-1 -> -0.53657781
B44: Cash and cash equivalents at end of period | C44: 29738 | D44: 43522 | E44: 40296 | F44: 38801 | H44: =D44/C44-1 -> 0.4635147 | I44: =E44/D44-1 -> -0.074123432 | J44: =F44/E44-1 -> -0.037100457
B45: Securities and time deposits and loans | C45: 49771 | D45: 41858 | E45: 44662 | F45: 47395 | H45: =D45/C45-1 -> -0.15898817 | I45: =E45/D45-1 -> 0.066988389 | J45: =F45/E45-1 -> 0.06119296
B46: Gross liquidity | C46: 79509 | D46: 85380 | E46: 84959 | F46: 86197 | H46: =D46/C46-1 -> 0.073840697 | I46: =E46/D46-1 -> -0.0049308972 | J46: =F46/E46-1 -> 0.014571735
B47: Total third-party borrowings | C47: -205312 | D47: -232813 | E47: -254081 | F47: -264703 | H47: =D47/C47-1 -> 0.13394736 | I47: =E47/D47-1 -> 0.091352287 | J47: =F47/E47-1 -> 0.041805566
B48: Net liquidity | C48: -125803 | D48: -147433 | E48: -169122 | F48: 178506 | H48: =D48/C48-1 -> 0.17193549 | I48: =E48/D48-1 -> 0.14711089 | J48: =F48/E48-1 -> -2.0554866

Sheet Statement of Changes In Equity
B1: Statement of Changes in Equity
B3: € in Millions | C3: Subscribed Capital | D3: Capital Revenue | E3: Retained Earnings | F3: Currency Translation Reserve | G3: Cash Flow Hedges(OCI I) | H3: Deferred Costs of Hedging(OCI II) | I3: Equity and debt instruments | J3: Equity-accounted investments | K3: Equity attributable to Volkswagen AG hybrid capital investors | L3: Equity attributable to Volkswagen AG shareholders and hybrid capital investors | M3: Noncontrolling interests | N3: Total equity
B4: Unadjusted balance at Jan. 1, 2022 | C4: 1283 | D4: 14551 | E4: 117342 | F4: -2351 | G4: -635 | H4: -367 | I4: -355 | J4: 541 | K4: 14439 | L4: 144449 | M4: 1705 | N4: 146154
B5: Changes in accounting policy to reflect IFRS 17 | C5: - | D5: - | E5: -11 | F5: - | G5: - | H5: - | I5: - | J5: 1 | K5: - | L5: -11 | M5: - | N5: -11
B6: Balance at Jan. 1, 2022 | C6: 1283 | D6: 14551 | E6: 117331 | F6: -2351 | G6: -635 | H6: -367 | I6: -355 | J6: 542 | K6: 14439 | L6: 144438 | M6: 1705 | N6: 146143
B7: Earnings after tax | C7: - | D7: - | E7: 14881 | F7: - | G7: - | H7: - | I7: - | J7: - | K7: 576 | L7: 15457 | M7: 395 | N7: 15852
B8: Other comprehensive income, net of tax | C8: - | D8: - | E8: 10243 | F8: 321 | G8: 1920 | H8: -885 | I8: -705 | J8: 325 | K8: - | L8: 11218 | M8: 241 | N8: 11459
B9: Total comprehensive income | C9: - | D9: - | E9: 25124 | F9: 321 | G9: 1920 | H9: -885 | I9: -705 | J9: 325 | K9: 576 | L9: 26676 | M9: 636 | N9: 27312
B10: Disposal of equity instruments | C10: - | D10: - | E10: -58 | F10: - | G10: - | H10: - | I10: 58 | J10: - | K10: - | L10: - | M10: - | N10: -
B11: Capital increases/Capital decreases | C11: - | D11: - | E11: - | F11: - | G11: - | H11: - | I11: - | J11: - | K11: -337 | L11: -337 | M11: 103 | N11: -234
B12: Dividends payment | C12: - | D12: - | E12: -13327 | F12: - | G12: - | H12: - | I12: - | J12: - | K12: -557 | L12: -13884 | M12: -257 | N12: -14141
B13: Capital transactions involving a change in ownership interest | C13: - | D13: - | E13: 8148 | F13: -226 | G13: 338 | H13: 174 | I13: -3 | J13: 0 | K13: - | L13: 8432 | M13: 10796 | N13: 19228
B14: Other changes | C14: - | D14: - | E14: 54 | F14: - | G14: - | H14: - | I14: - | J14: -3 | K14: - | L14: 51 | M14: -30 | N14: 21
B15: Balance at Dec. 31, 2022 | C15: 1283 | D15: 14551 | E15: 137272 | F15: -2256 | G15: 1623 | H15: -1077 | I15: -1005 | J15: 864 | K15: 14121 | L15: 165376 | M15: 12952 | N15: 178328
B17: Unadjusted balance at Jan. 1, 2023 | C17: 1283 | D17: 14551 | E17: 137267 | F17: -2256 | G17: 1623 | H17: -1077 | I17: -1005 | J17: 870 | K17: 14121 | L17: 165378 | M17: 12950 | N17: 178327
B18: Changes in accounting policy to reflect IFRS 17 | C18: - | D18: - | E18: 5 | F18: - | G18: - | H18: - | I18: - | J18: -7 | K18: - | L18: -1 | M18: 2 | N18: 1
B19: Balance at Jan. 1, 2023 | C19: 1283 | D19: 14551 | E19: 137272 | F19: -2256 | G19: 1623 | H19: -1077 | I19: -1005 | J19: 864 | K19: 14121 | L19: 165376 | M19: 12952 | N19: 178328
B20: Earnings after tax | C20: - | D20: - | E20: 16013 | F20: - | G20: - | H20: - | I20: - | J20: - | K20: 586 | L20: 16599 | M20: 1329 | N20: 17928
B21: Other comprehensive income, net of tax | C21: - | D21: - | E21: -1153 | F21: -1163 | G21: -151 | H21: 401 | I21: 52 | J21: -388 | K21: - | L21: -2402 | M21: 64 | N21: -2339
B22: Total comprehensive income | C22: - | D22: - | E22: 14860 | F22: -1163 | G22: -151 | H22: 401 | I22: 52 | J22: -388 | K22: 586 | L22: 14197 | M22: 1393 | N22: 15589
B23: Disposal of equity instruments | C23: - | D23: - | E23: 13 | F23: - | G23: - | H23: - | I23: -13 | J23: - | K23: - | L23: - | M23: - | N23: -
B24: Capital increases/Capital decreases | C24: - | D24: - | E24: - | F24: - | G24: - | H24: - | I24: - | J24: - | K24: 1004 | L24: 1004 | M24: 3 | N24: 1008
B25: Dividends payment | C25: - | D25: - | E25: -4374 | F25: - | G25: - | H25: - | I25: - | J25: - | K25: -556 | L25: -4930 | M25: -54 | N25: -4984
B26: Capital transactions involving a change in ownership interest | C26: - | D26: - | E26: -42 | F26: -11 | G26: - | H26: - | I26: - | J26: - | K26: - | L26: -54 | M26: -27 | N26: -80
B27: Other changes | C27: - | D27: - | E27: 100 | F27: - | G27: - | H27: - | I27: - | J27: - | K27: - | L27: 100 | M27: -50 | N27: 51
B28: Balance at Dec. 31, 2023 | C28: 1283 | D28: 14551 | E28: 147830 | F28: -3431 | G28: 1472 | H28: -676 | I28: -966 | J28: 476 | K28: 15155 | L28: 175694 | M28: 14218 | N28: 189912
B30: Unadjusted balance at Jan. 1, 2024 | C30: 1283 | D30: 14551 | E30: 147830 | F30: -3431 | G30: 1472 | H30: -676 | I30: -966 | J30: 476 | K30: 15155 | L30: 175694 | M30: 14218 | N30: 189912
B31: Prior-year corrections in accordance with IAS 8 | C31: - | D31: - | E31: -726 | F31: - | G31: - | H31: - | I31: - | J31: - | K31: - | L31: -726 | M31: - | N31: -726
B32: Balance at Jan. 1, 2024 | C32: 1283 | D32: 14551 | E32: 147104 | F32: -3431 | G32: 1472 | H32: -676 | I32: -966 | J32: 476 | K32: 15155 | L32: 174968 | M32: 14218 | N32: 189186
B33: Earnings after tax | C33: - | D33: - | E33: 10721 | F33: - | G33: - | H33: - | I33: - | J33: - | K33: 630 | L33: 11351 | M33: 1043 | N33: 12394
B34: Other comprehensive income, net of tax | C34: - | D34: - | E34: 1589 | F34: 1275 | G34: -1006 | H34: 409 | I34: 61 | J34: -174 | K34: - | L34: 2154 | M34: -183 | N34: 1971
B35: Total comprehensive income | C35: - | D35: - | E35: 12310 | F35: 1275 | G35: -1006 | H35: 409 | I35: 61 | J35: -174 | K35: 630 | L35: 13505 | M35: 860 | N35: 14365
B36: Disposal of equity instruments | C36: - | D36: - | E36: 1 | F36: - | G36: - | H36: - | I36: -1 | J36: - | K36: - | L36: - | M36: - | N36: -
B37: Capital increases/Capital decreases | C37: - | D37: - | E37: - | F37: - | G37: - | H37: - | I37: - | J37: - | K37: -1244 | L37: -1244 | M37: 106 | N37: -1138
B38: Dividends payment | C38: - | D38: - | E38: -4524 | F38: - | G38: - | H38: - | I38: - | J38: - | K38: -651 | L38: -5175 | M38: -604 | N38: -5779
B39: Capital transactions involving a change in ownership interest | C39: - | D39: - | E39: -4 | F39: 0 | G39: - | H39: - | I39: - | J39: - | K39: - | L39: -4 | M39: 4 | N39: -
B40: Other changes | C40: - | D40: - | E40: 243 | F40: - | G40: - | H40: - | I40: - | J40: 1 | K40: - | L40: 244 | M40: -147 | N40: 97
B41: Balance at Dec. 31, 2024 | C41: 1283 | D41: 14551 | E41: 155130 | F41: -2156 | G41: 466 | H41: -267 | I41: -906 | J41: 303 | K41: 13890 | L41: 182294 | M41: 14437 | N41: 196731
B43: Balance at Jan. 1, 2025 | C43: 1283 | D43: 14551 | E43: 155130 | F43: -2156 | G43: 466 | H43: -267 | I43: -906 | J43: 303 | K43: 13890 | L43: 182294 | M43: 14437 | N43: 196731
B44: Earnings after tax | C44: - | D44: - | E44: 6673 | F44: - | G44: - | H44: - | I44: - | J44: - | K44: 650 | L44: 7323 | M44: -419 | N44: 6904
...

Sheet Activity Ratios
B1: Activity Ratios
B3: Ratio | E3: Year(2023) | I3: Year(2024) | M3: Year(2025) | Q3: Meaning
B5: 1. Receivables turnover = | C5: annual sales | E5: ='P&L'!D4 -> 322284 | F5: = | G5: =E5/E6 -> 15.96137 | I5: ='P&L'!E4 -> 324656 | J5: = | K5: =I5/I6 -> 15.107657 | M5: ='P&L'!F4 -> 321913 | N5: = | O5: =M5/M6 -> 15.369444 | Q5: The efficiency of a company in collecting its trade receivables
C6: average receivables | E6: =AVERAGE('Balance Sheet'!C21,'Balance Sheet'!D21) -> 20191.5 | I6: =AVERAGE('Balance Sheet'!D21,'Balance Sheet'!E21) -> 21489.5 | M6: =AVERAGE('Balance Sheet'!E21,'Balance Sheet'!F21) -> 20945
B9: 2. Days of sales outstanding = | C9: 365 | E9: 365 | F9: = | G9: =E9/E10 -> 22.867711 | I9: 365 | J9: = | K9: =I9/I10 -> 24.159934 | M9: 365 | N9: = | O9: =M9/M10 -> 23.74842 | Q9: The average number of days a company takes to collect its receivables from clients
C10: receivables turnover | E10: =G5 -> 15.96137 | I10: =K5 -> 15.107657 | M10: =O5 -> 15.369444
B13: 3. Inventory turnover = | C13: cost of goods sold | E13: =-'P&L'!D5 -> 261262 | F13: = | G13: =E13/E14 -> 4.9352916 | I13: =-'P&L'!E5 -> 265184 | J13: = | K13: =I13/I14 -> 4.8074981 | M13: =-'P&L'!F5 -> 270671 | N13: = | O13: =M13/M14 -> 4.8007485 | Q13: The efficiency of a company in terms of inventory management
C14: average inventory | E14: =AVERAGE('Balance Sheet'!C20,'Balance Sheet'!D20) -> 52937.5 | I14: =AVERAGE('Balance Sheet'!D20,'Balance Sheet'!E20) -> 55160.5 | M14: =AVERAGE('Balance Sheet'!E20,'Balance Sheet'!F20) -> 56381
B17: 4. Days of inventory on hand = | C17: 365 | E17: 365 | F17: = | G17: =E17/E18 -> 73.957129 | I17: 365 | J17: = | K17: =I17/I18 -> 75.923067 | M17: 365 | N17: = | O17: =M17/M18 -> 76.029811 | Q17: The average inventory processing period
C18: inventory turnover | E18: =G13 -> 4.9352916 | I18: =K13 -> 4.8074981 | M18: =O13 -> 4.8007485
B21: 5. Payables turnover = | C21: purchases | E21: =('Balance Sheet'!D20-'Balance Sheet'!C20)+(-'P&L'!D5) -> 262589 | F21: = | G21: =E21/E22 -> 8.8059491 | I21: =('Balance Sheet'!E20-'Balance Sheet'!D20)+(-'P&L'!E5) -> 268303 | J21: = | K21: =I21/I22 -> 8.8442305 | M21: =('Balance Sheet'!E20-'Balance Sheet'!F20)+(-'P&L'!F5) -> 271349 | N21: = | O21: =M21/M22 -> 9.005642 | Q21: The efficiency of a company in allowing trade credit to suppliers
C22: average trade payables | E22: =AVERAGE('Balance Sheet'!C57,'Balance Sheet'!D57) -> 29819.5 | I22: =AVERAGE('Balance Sheet'!D57,'Balance Sheet'!E57) -> 30336.5 | M22: =AVERAGE('Balance Sheet'!E57,'Balance Sheet'!F57) -> 30131
Q23: * Purchases = ending inventory – beginning inventory + cost of goods sold
B25: 6. Number of days of payables = | C25: 365 | E25: 365 | F25: = | G25: =E25/E26 -> 41.449251 | I25: 365 | J25: = | K25: =I25/I26 -> 41.269842 | M25: 365 | N25: = | O25: =M25/M26 -> 40.530148 | Q25: The average number of days a company takes to pay its suppliers
C26: payables turnover | E26: =G21 -> 8.8059491 | I26: =K21 -> 8.8442305 | M26: =O21 -> 9.005642
B29: 7. Fixed assets turnover = | C29: revenue | E29: ='P&L'!D4 -> 322284 | F29: = | G29: =E29/E30 -> 4.9290204 | I29: ='P&L'!E4 -> 324656 | J29: = | K29: =I29/I30 -> 4.6938669 | M29: ='P&L'!F4 -> 321913 | N29: = | O29: =M29/M30 -> 3.483775 | Q29: The efficiency of a firm in utilizing its fixed assets
C30: average net fixed assets | E30: =AVERAGE('Balance Sheet'!C7,'Balance Sheet'!D7) -> 65385 | I30: =AVERAGE('Balance Sheet'!D7,'Balance Sheet'!E7) -> 69166 | M30: =AVERAGE('Balance Sheet'!E6,'Balance Sheet'!F6) -> 92403.5
B33: 8. Working capital turnover = | C33: revenue | E33: ='P&L'!D4 -> 322284 | F33: = | G33: =E33/E34 -> 8.5706991 | I33: ='P&L'!E4 -> 324656 | J33: = | K33: =I33/I34 -> 10.479197 | M33: ='P&L'!F4 -> 321913 | N33: = | O33: =M33/M34 -> 12.998183 | Q33: The efficiency of a firm in managing its working capital (current assets - current liabilities)
C34: average working capital | E34: =AVERAGE('Balance Sheet'!C29,'Balance Sheet'!D29)-AVERAGE('Balance Sheet'!C64,'Balance Sheet'!D64) -> 37603 | I34: =AVERAGE('Balance Sheet'!D29,'Balance Sheet'!E29)-AVERAGE('Balance Sheet'!D64,'Balance Sheet'!E64) -> 30981 | M34: =AVERAGE('Balance Sheet'!E29,'Balance Sheet'!F29)-AVERAGE('Balance Sheet'!E64,'Balance Sheet'!F64) -> 24766
B37: 9. Total assets turnover = | C37: revenue | E37: ='P&L'!D4 -> 322284 | F37: = | G37: =E37/E38 -> 0.55358565 | I37: ='P&L'!E4 -> 324656 | J37: = | K37: =I37/I38 -> 0.52650775 | M37: ='P&L'!F4 -> 321913 | N37: = | O37: =M37/M38 -> 0.50402389 | Q37: The efficiency of a firm in using its total assets to create revenue
C38: average total assets | E38: =AVERAGE('Balance Sheet'!C31,'Balance Sheet'!D31) -> 582175.5 | I38: =AVERAGE('Balance Sheet'!D31,'Balance Sheet'!E31) -> 616621.5 | M38: =AVERAGE('Balance Sheet'!E31,'Balance Sheet'!F31) -> 638686
B41: 10. Cash conversion cycle = | C41: days of sales outstanding | E41: =G9 -> 22.867711 | F41: = | G41: =E41+E43-E45 -> 55.375589 | I41: =K9 -> 24.159934 | J41: = | K41: =I41+I43-I45 -> 58.813158 | M41: =O9 -> 23.74842 | N41: = | O41: =M41+M43-M45 -> 59.248083 | Q41: The number of days a company takes to convert its investments in inventory and other resources into cash flows from sales
E42: + | I42: + | M42: +
C43: plus: days of inventory on hand | E43: =G17 -> 73.957129 | I43: =K17 -> 75.923067 | M43: =O17 -> 76.029811
E44: - | I44: - | M44: -
C45: less: number of days of payables | E45: =G25 -> 41.449251 | I45: =K25 -> 41.269842 | M45: =O25 -> 40.530148
B48: 11. Equity turnover = | C48: revenue | E48: ='P&L'!D4 -> 322284 | F48: = | G48: =E48/E49 -> 1.7504019 | I48: ='P&L'!E4 -> 324656 | J48: = | K48: =I48/I49 -> 1.679358 | M48: ='P&L'!F4 -> 321913 | N48: = | O48: =M48/M49 -> 1.6104306 | Q48: The efficiency of a firm in utilizing equity to create revenue
C49: average total equity | E49: =AVERAGE('Balance Sheet'!C43,'Balance Sheet'!D43) -> 184120 | I49: =AVERAGE('Balance Sheet'!D43,'Balance Sheet'!E43) -> 193321.5 | M49: =AVERAGE('Balance Sheet'!E43,'Balance Sheet'!F43) -> 199892.5

Sheet Liquidity Ratios
B1: Liquidity Ratios
B3: Ratio | E3: Year(2023) | I3: Year(2024) | M3: Year(2025) | Q3: Meaning
B5: 1. Current ratio = | C5: current assets | E5: ='Balance Sheet'!D29 -> 239644 | F5: = | G5: =E5/E6 -> 1.1640324 | I5: ='Balance Sheet'!E29 -> 245231 | J5: = | K5: =I5/I6 -> 1.1298937 | M5: ='Balance Sheet'!F29 -> 247865 | N5: = | O5: =M5/M6 -> 1.0942059 | Q5: Ability to meet current liabilities (with total current assets)
C6: current liabilities | E6: ='Balance Sheet'!D64 -> 205874 | I6: ='Balance Sheet'!E64 -> 217039 | M6: ='Balance Sheet'!F64 -> 226525
B9: 2. Quick ratio = | C9: cash + marketable securities + receivables | E9: =SUM('Balance Sheet'!D21+'Balance Sheet'!D26+'Balance Sheet'!D27) -> 92070 | F9: = | G9: =E9/E10 -> 0.44721529 | I9: =SUM('Balance Sheet'!E21+'Balance Sheet'!E26+'Balance Sheet'!E27) -> 88752 | J9: = | K9: =I9/I10 -> 0.4089219 | M9: =SUM('Balance Sheet'!F21+'Balance Sheet'!F26+'Balance Sheet'!F27) -> 89083 | N9: = | O9: =M9/M10 -> 0.39325902 | Q9: Ability to meet current liabilities (with total current assets, excluding inventory)
C10: current liabilities | E10: ='Balance Sheet'!D64 -> 205874 | I10: ='Balance Sheet'!E64 -> 217039 | M10: ='Balance Sheet'!F64 -> 226525
B13: 3. Cash ratio = | C13: cash + marketable securities | E13: ='Balance Sheet'!D27+'Balance Sheet'!D26 -> 70221 | F13: = | G13: =E13/E14 -> 0.34108727 | I13: ='Balance Sheet'!E27+'Balance Sheet'!E26 -> 67622 | J13: = | K13: =I13/I14 -> 0.31156612 | M13: ='Balance Sheet'!F27+'Balance Sheet'!F26 -> 68323 | N13: = | O13: =M13/M14 -> 0.30161351 | Q13: Ability to meet current liabilities (with cash and marketable securities only)
C14: current liabilities | E14: ='Balance Sheet'!D64 -> 205874 | I14: ='Balance Sheet'!E64 -> 217039 | M14: ='Balance Sheet'!F64 -> 226525
B17: 4. Defensive interval = | C17: cash + marketable securities + receivables | E17: ='Balance Sheet'!D27+'Balance Sheet'!D26+'Balance Sheet'!D21 -> 92070 | F17: = | G17: =E17/E18 -> 106.73172 | I17: ='Balance Sheet'!E27+'Balance Sheet'!E26+'Balance Sheet'!E21 -> 88752 | J17: = | K17: =I17/I18 -> 101.05275 | M17: ='Balance Sheet'!F27+'Balance Sheet'!F26+'Balance Sheet'!F21 -> 89083 | N17: = | O17: =M17/M18 -> 99.538649 | Q17: The number of days a company can cover its average daily expenses with the use of current liquid assets only
C18: average daily expenditure | E18: =-('P&L'!D5+'P&L'!D7+'P&L'!D8+'P&L'!D10)/365 -> 862.63014 | I18: =-('P&L'!E5+'P&L'!E7+'P&L'!E8+'P&L'!E10)/365 -> 878.27397 | M18: =-('P&L'!F5+'P&L'!F7+'P&L'!F8+'P&L'!F10)/365 -> 894.9589
Q20: Avg Daily Expenidture = (COGS+Opex)/365

Sheet Solvency Ratios
B1: Solvency Ratios
B3: Ratio | E3: Year(2023) | I3: Year(2024) | M3: Year(2025) | Q3: Meaning
B5: 1. Debt-to-equity = | C5: total debt | E5: =('Balance Sheet'!$D$46+'Balance Sheet'!$D$47+'Balance Sheet'!$D$56+'Balance Sheet'!$D$59) -> 253789 | F5: = | G5: =E5/E6 -> 1.3363505 | I5: =('Balance Sheet'!$E$46+'Balance Sheet'!$E$47+'Balance Sheet'!$E$56+'Balance Sheet'!$E$59) -> 274993 | J5: = | K5: =I5/I6 -> 1.3978122 | M5: =('Balance Sheet'!$F$46+'Balance Sheet'!$F$47+'Balance Sheet'!$F$56+'Balance Sheet'!$F$59) -> 284768 | N5: = | O5: =M5/M6 -> 1.402425 | Q5: Debt as a percentage of total equity
C6: total shareholder's equity | E6: ='Balance Sheet'!$D$43 -> 189912 | I6: ='Balance Sheet'!$E$43 -> 196731 | M6: ='Balance Sheet'!$F$43 -> 203054
B9: 2. Debt-to-capital = | C9: total debt | E9: =('Balance Sheet'!$D$46+'Balance Sheet'!$D$47+'Balance Sheet'!$D$56+'Balance Sheet'!$D$59) -> 253789 | F9: = | G9: =E9/E10 -> 0.57198203 | I9: =('Balance Sheet'!$E$46+'Balance Sheet'!$E$47+'Balance Sheet'!$E$56+'Balance Sheet'!$E$59) -> 274993 | J9: = | K9: =I9/I10 -> 0.58295317 | M9: =('Balance Sheet'!$F$46+'Balance Sheet'!$F$47+'Balance Sheet'!$F$56+'Balance Sheet'!$F$59) -> 284768 | N9: = | O9: =M9/M10 -> 0.58375391 | Q9: Debt as a percentage of total capital
C10: total debt + total shareholder's equity | E10: =('Balance Sheet'!$D$46+'Balance Sheet'!$D$47+'Balance Sheet'!$D$59+'Balance Sheet'!$D$56)+('Balance Sheet'!$D$43) -> 443701 | I10: =('Balance Sheet'!$E$46+'Balance Sheet'!$E$47+'Balance Sheet'!$E$59+'Balance Sheet'!$E$56)+('Balance Sheet'!$E$43) -> 471724 | M10: =('Balance Sheet'!$F$46+'Balance Sheet'!$F$47+'Balance Sheet'!$F$59+'Balance Sheet'!$F$56)+('Balance Sheet'!$F$43) -> 487822
B13: 3. Debt-to-assets = | C13: total debt | E13: =('Balance Sheet'!$D$46+'Balance Sheet'!$D$47+'Balance Sheet'!$D$56+'Balance Sheet'!$D$59) -> 253789 | F13: = | G13: =E13/E14 -> 0.42274352 | I13: =('Balance Sheet'!$E$46+'Balance Sheet'!$E$47+'Balance Sheet'!$E$56+'Balance Sheet'!$E$59) -> 274993 | J13: = | K13: =I13/I14 -> 0.43449333 | M13: =('Balance Sheet'!$F$46+'Balance Sheet'!$F$47+'Balance Sheet'!$F$56+'Balance Sheet'!$F$59) -> 284768 | N13: = | O13: =M13/M14 -> 0.44186591 | Q13: Debt as a percentage of total assets
C14: total assets | E14: ='Balance Sheet'!$D$31 -> 600338 | I14: ='Balance Sheet'!$E$31 -> 632905 | M14: ='Balance Sheet'!$F$31 -> 644467
B17: 4. Interest coverage = | C17: earnings before interest and taxes | E17: ='P&L'!$D$11 -> 22576 | F17: = | G17: =E17/E18 -> 6.285078 | I17: ='P&L'!$E$11 -> 19060 | J17: = | K17: =I17/I18 -> 5.5310505 | M17: ='P&L'!$F$11 -> 8868 | N17: = | O17: =M17/M18 -> 2.7328197 | Q17: The ability to cover interest expenses
C18: interest payments | E18: =-'P&L'!$D$14 -> 3592 | I18: =-'P&L'!$E$14 -> 3446 | M18: =-'P&L'!$F$14 -> 3245
B21: 5. Fixed charge coverage = | C21: earnings before interest and taxes + lease payments | E21: =('P&L'!$D$11-'P&L'!$D$14) -> 26168 | F21: = | G21: =E21/E22 -> 4.6912872 | I21: =('P&L'!$E$11-'P&L'!$E$14) -> 22506 | J21: = | K21: =I21/I22 -> 4.0595238 | M21: =('P&L'!$F$11-'P&L'!$F$14) -> 12113 | N21: = | O21: =M21/M22 -> 2.2246097 | Q21: The ability to cover interest and lease expenses
C22: interest payments + lease payments | E22: =('P&L'!$D$23-'P&L'!$D$14) -> 5578 | I22: =('P&L'!$E$23-'P&L'!$E$14) -> 5544 | M22: =('P&L'!$F$23-'P&L'!$F$14) -> 5445
B25: 6. Financial leverage = | C25: average total assets | E25: =AVERAGE('Balance Sheet'!$C$31,'Balance Sheet'!$D$31) -> 582175.5 | F25: = | G25: =E25/E26 -> 3.1619352 | I25: =AVERAGE('Balance Sheet'!$E$31,'Balance Sheet'!$D$31) -> 616621.5 | J25: = | K25: =I25/I26 -> 3.1896168 | M25: =AVERAGE('Balance Sheet'!$E$31,'Balance Sheet'!$F$31) -> 638686 | N25: = | O25: =M25/M26 -> 3.1951474 | Q25: An indicator of a company's debt financing usage
C26: average total equity | E26: =AVERAGE('Balance Sheet'!$C$43,'Balance Sheet'!$D$43) -> 184120 | I26: =AVERAGE('Balance Sheet'!$E$43,'Balance Sheet'!$D$43) -> 193321.5 | M26: =AVERAGE('Balance Sheet'!$E$43,'Balance Sheet'!$F$43) -> 199892.5

Sheet Profitability Ratios
B1: Profitability Ratios
B3: Ratio | E3: Year(2023) | I3: Year(2024) | M3: Year(2025) | Q3: Meaning
B5: 1. Gross profit margin = | C5: gross profit | E5: ='P&L'!$D$6 -> 61022 | F5: = | G5: =E5/E6 -> 0.18934232 | I5: ='P&L'!$E$6 -> 59472 | J5: = | K5: =I5/I6 -> 0.18318466 | M5: ='P&L'!$F$6 -> 51243 | N5: = | O5: =M5/M6 -> 0.15918276 | Q5: Gross profitability as a percentage of total revenue
C6: revenue | E6: ='P&L'!$D$4 -> 322284 | I6: ='P&L'!$E$4 -> 324656 | M6: ='P&L'!$F$4 -> 321913
B9: 2. Operating profit margin = | C9: operating income (EBIT) | E9: ='P&L'!$D$11 -> 22576 | F9: = | G9: =E9/E10 -> 0.070050018 | I9: ='P&L'!$E$11 -> 19060 | J9: = | K9: =I9/I10 -> 0.058708294 | M9: ='P&L'!$F$11 -> 8868 | N9: = | O9: =M9/M10 -> 0.027547816 | Q9: Operating profitability (before interest and tax) as a percentage of total revenue
C10: revenue | E10: ='P&L'!$D$4 -> 322284 | I10: ='P&L'!$E$4 -> 324656 | M10: ='P&L'!$F$4 -> 321913
B13: 3. Pretax margin = | C13: EBT | E13: ='P&L'!$D$17 -> 23194 | F13: = | G13: =E13/E14 -> 0.071967581 | I13: ='P&L'!$E$17 -> 16806 | J13: = | K13: =I13/I14 -> 0.051765561 | M13: ='P&L'!$F$17 -> 9307 | N13: = | O13: =M13/M14 -> 0.028911538 | Q13: Operating profitability (before tax) as a percentage of total revenue
C14: revenue | E14: ='P&L'!$D$4 -> 322284 | I14: ='P&L'!$E$4 -> 324656 | M14: ='P&L'!$F$4 -> 321913
B17: 4. Net profit margin = | C17: net income | E17: ='P&L'!$D$21 -> 17928 | F17: = | G17: =E17/E18 -> 0.055627955 | I17: ='P&L'!$E$21 -> 12394 | J17: = | K17: =I17/I18 -> 0.038175792 | M17: ='P&L'!$F$21 -> 6904 | N17: = | O17: =M17/M18 -> 0.021446788 | Q17: Net profitability as a percentage of total revenue
C18: revenue | E18: ='P&L'!$D$4 -> 322284 | I18: ='P&L'!$E$4 -> 324656 | M18: ='P&L'!$F$4 -> 321913
B21: 5. Return on assets (ROA) = | C21: net income | E21: ='P&L'!$D$21 -> 17928 | F21: = | G21: =E21/E22 -> 0.030794838 | I21: ='P&L'!$E$21 -> 12394 | J21: = | K21: =I21/I22 -> 0.020099851 | M21: ='P&L'!$F$21 -> 6904 | N21: = | O21: =M21/M22 -> 0.010809694 | Q21: Net profitability (excluding interest and taxes) as a percentage of total invested funds
C22: average total assets | E22: =AVERAGE('Balance Sheet'!$C$31,'Balance Sheet'!$D$31) -> 582175.5 | I22: =AVERAGE('Balance Sheet'!$E$31,'Balance Sheet'!$D$31) -> 616621.5 | M22: =AVERAGE('Balance Sheet'!$E$31,'Balance Sheet'!$F$31) -> 638686
B25: 6. Operating return on assets (ROA) = | C25: operating profit (EBIT) | E25: ='P&L'!$D$11 -> 22576 | F25: = | G25: =E25/E26 -> 0.038778684 | I25: ='P&L'!$E$11 -> 19060 | J25: = | K25: =I25/I26 -> 0.030910372 | M25: ='P&L'!$F$11 -> 8868 | N25: = | O25: =M25/M26 -> 0.013884757 | Q25: Net profitability (including interest and taxes) as a percentage of total invested funds
C26: average total assets | E26: =AVERAGE('Balance Sheet'!$C$31,'Balance Sheet'!$D$31) -> 582175.5 | I26: =AVERAGE('Balance Sheet'!$E$31,'Balance Sheet'!$D$31) -> 616621.5 | M26: =AVERAGE('Balance Sheet'!$E$31,'Balance Sheet'!$F$31) -> 638686
B29: 7. Return on total capital = | C29: operating profit (EBIT) | E29: ='P&L'!$D$11 -> 22576 | F29: = | G29: =E29/E30 -> 0.052796451 | I29: ='P&L'!$E$11 -> 19060 | J29: = | K29: =I29/I30 -> 0.04164186 | M29: ='P&L'!$F$11 -> 8868 | N29: = | O29: =M29/M30 -> 0.018483741 | Q29: Operating profitability as a percentage of total capital
C30: average total capital | E30: =AVERAGE('Balance Sheet'!$C$43,'Balance Sheet'!$D$43)+AVERAGE('Balance Sheet'!$C$46,'Balance Sheet'!$D$46)+AVERAGE('Balance Sheet'!$C$47,'Balance Sheet'!$D$47)+AVERAGE('Balance Sheet'!$C$56,'Balance Sheet'!$D$56)+AVERAGE('Balance Sheet'!$C$59,'Balance Sheet'!$D$59) -> 427604.5 | I30: =AVERAGE('Balance Sheet'!$E$43,'Balance Sheet'!$D$43)+AVERAGE('Balance Sheet'!$E$46,'Balance Sheet'!$D$46)+AVERAGE('Balance Sheet'!$E$47,'Balance Sheet'!$D$47)+AVERAGE('Balance Sheet'!$E$56,'Balance Sheet'!$D$56)+AVERAGE('Balance Sheet'!$E$59,'Balance Sheet'!$D$59) -> 457712.5 | M30: =AVERAGE('Balance Sheet'!$E$43,'Balance Sheet'!$F$43)+AVERAGE('Balance Sheet'!$E$46,'Balance Sheet'!$F$46)+AVERAGE('Balance Sheet'!$E$47,'Balance Sheet'!$F$47)+AVERAGE('Balance Sheet'!$E$56,'Balance Sheet'!$F$56)+AVERAGE('Balance Sheet'!$E$59,'Balance Sheet'!$F$59) -> 479773
B33: 8. Return on equity (RoE)= | C33: net income | E33: ='P&L'!$D$21 -> 17928 | F33: = | G33: =E33/E34 -> 0.09737128 | I33: ='P&L'!$E$21 -> 12394 | J33: = | K33: =I33/I34 -> 0.064110821 | M33: ='P&L'!$F$21 -> 6904 | N33: = | O33: =M33/M34 -> 0.034538564 | Q33: Net profitability as a percentage of total equity
C34: average equity | E34: =AVERAGE('Balance Sheet'!$C$43,'Balance Sheet'!$D$43) -> 184120 | I34: =AVERAGE('Balance Sheet'!$E$43,'Balance Sheet'!$D$43) -> 193321.5 | M34: =AVERAGE('Balance Sheet'!$E$43,'Balance Sheet'!$F$43) -> 199892.5

Sheet Valuation Ratios
B1: Valuation Ratios
B3: Ratio | E3: Year(2023) | I3: Year(2024) | M3: Year(2025) | Q3: Meaning
B5: 1. Earnings per common share (EPCS) = | C5: Net Income - preferred dividends | E5: ='P&L'!$D$31*1000000 -> 9419000000 | F5: = | G5: =E5/E6 -> 31.919095 | I5: ='P&L'!$E$31*1000000 -> 6304000000 | J5: = | K5: =I5/I6 -> 21.362987 | M5: ='P&L'!$F$31*1000000 -> 3921000000 | N5: = | O5: =M5/M6 -> 13.28748 | Q5: Income earned per 1 common share outstanding
C6: Outstanding number of common shares | E6: ='P&L'!$D$25 -> 295089818 | I6: ='P&L'!$E$25 -> 295089818 | M6: ='P&L'!$F$25 -> 295089818
B9: 2. Common Price earnings (P/E) ratio = | C9: Share price | E9: ='P&L'!$D$33 -> 118.45 | F9: = | G9: =E9/E10 -> 3.7109448 | I9: ='P&L'!$E$33 -> 92.15 | J9: = | K9: =I9/I10 -> 4.3135353 | M9: ='P&L'!$F$33 -> 105.1 | N9: = | O9: =M9/M10 -> 7.9097016 | Q9: The price that investors are willing to pay per $1 of earnings
C10: Earnings per share (EPCS) | E10: =G5 -> 31.919095 | I10: =K5 -> 21.362987 | M10: =O5 -> 13.28748
B13: 1. Earnings per Preffered share (EPPS) = | C13: Net Income - Common Share dividends | E13: ='P&L'!$D$32*1000000 -> 6594000000 | F13: = | G13: =E13/E14 -> 31.977817 | I13: ='P&L'!$E$32*1000000 -> 4417000000 | J13: = | K13: =I13/I14 -> 21.420385 | M13: ='P&L'!$F$32*1000000 -> 2752000000 | N13: = | O13: =M13/M14 -> 13.345913 | Q13: Income earned per 1 Preferred share outstanding
C14: Outstanding number of common shares | E14: ='P&L'!$D$26 -> 206205445 | I14: ='P&L'!$E$26 -> 206205445 | M14: ='P&L'!$F$26 -> 206205445
B17: 2. Preffered Price earnings (P/E) ratio = | C17: Share price | E17: ='P&L'!$D$34 -> 111.8 | F17: = | G17: =E17/E18 -> 3.4961736 | I17: ='P&L'!$E$34 -> 89.04 | J17: = | K17: =I17/I18 -> 4.1567881 | M17: ='P&L'!$F$34 -> 103.55 | N17: = | O17: =M17/M18 -> 7.7589294 | Q17: The price that investors are willing to pay per $1 of earnings
C18: Earnings per share (EPPS) | E18: =G13 -> 31.977817 | I18: =K13 -> 21.420385 | M18: =O13 -> 13.345913
B21: 3. P/E ratio (company wide) = | C21: Market capitalization | E21: ='P&L'!$D$35 -> 58000 | F21: = | G21: =E21/E22 -> 3.2351629 | I21: ='P&L'!$E$35 -> 45600 | J21: = | K21: =I21/I22 -> 3.6791996 | M21: ='P&L'!$F$35 -> 52400 | N21: = | O21: =M21/M22 -> 7.589803 | Q21: Total price that investors are willing to pay for a company's Net income
